[2024-04-06T17:01:46.909+0000] {taskinstance.py:1979} INFO - Dependencies all met for dep_context=non-requeueable deps ti=<TaskInstance: data_processing_dag.standardize_data manual__2024-04-06T16:59:20.220565+00:00 [queued]>
[2024-04-06T17:01:46.926+0000] {taskinstance.py:1979} INFO - Dependencies all met for dep_context=requeueable deps ti=<TaskInstance: data_processing_dag.standardize_data manual__2024-04-06T16:59:20.220565+00:00 [queued]>
[2024-04-06T17:01:46.926+0000] {taskinstance.py:2193} INFO - Starting attempt 1 of 2
[2024-04-06T17:01:46.970+0000] {taskinstance.py:2217} INFO - Executing <Task(PythonOperator): standardize_data> on 2024-04-06 16:59:20.220565+00:00
[2024-04-06T17:01:46.975+0000] {standard_task_runner.py:60} INFO - Started process 545 to run task
[2024-04-06T17:01:46.977+0000] {standard_task_runner.py:87} INFO - Running: ['airflow', 'tasks', 'run', 'data_processing_dag', 'standardize_data', 'manual__2024-04-06T16:59:20.220565+00:00', '--job-id', '39', '--raw', '--subdir', 'DAGS_FOLDER/download_NASA_API_dags.py', '--cfg-path', '/tmp/tmpi_c9wnpg']
[2024-04-06T17:01:46.979+0000] {standard_task_runner.py:88} INFO - Job 39: Subtask standardize_data
[2024-04-06T17:01:47.061+0000] {task_command.py:423} INFO - Running <TaskInstance: data_processing_dag.standardize_data manual__2024-04-06T16:59:20.220565+00:00 [running]> on host 29c65f98c54a
[2024-04-06T17:01:47.180+0000] {taskinstance.py:2513} INFO - Exporting env vars: AIRFLOW_CTX_DAG_OWNER='airflow' AIRFLOW_CTX_DAG_ID='data_processing_dag' AIRFLOW_CTX_TASK_ID='standardize_data' AIRFLOW_CTX_EXECUTION_DATE='2024-04-06T16:59:20.220565+00:00' AIRFLOW_CTX_TRY_NUMBER='1' AIRFLOW_CTX_DAG_RUN_ID='manual__2024-04-06T16:59:20.220565+00:00'
[2024-04-06T17:01:47.181+0000] {taskinstance.py:2731} ERROR - Task failed with exception
Traceback (most recent call last):
  File "/home/airflow/.local/lib/python3.8/site-packages/airflow/models/taskinstance.py", line 444, in _execute_task
    result = _execute_callable(context=context, **execute_callable_kwargs)
  File "/home/airflow/.local/lib/python3.8/site-packages/airflow/models/taskinstance.py", line 414, in _execute_callable
    return execute_callable(context=context, **execute_callable_kwargs)
  File "/home/airflow/.local/lib/python3.8/site-packages/airflow/operators/python.py", line 200, in execute
    return_value = self.execute_callable()
  File "/home/airflow/.local/lib/python3.8/site-packages/airflow/operators/python.py", line 217, in execute_callable
    return self.python_callable(*self.op_args, **self.op_kwargs)
TypeError: standardize_data() missing 1 required positional argument: 'df_combinado'
[2024-04-06T17:01:47.191+0000] {taskinstance.py:1149} INFO - Marking task as UP_FOR_RETRY. dag_id=data_processing_dag, task_id=standardize_data, execution_date=20240406T165920, start_date=20240406T170146, end_date=20240406T170147
[2024-04-06T17:01:47.225+0000] {standard_task_runner.py:107} ERROR - Failed to execute job 39 for task standardize_data (standardize_data() missing 1 required positional argument: 'df_combinado'; 545)
[2024-04-06T17:01:47.271+0000] {local_task_job_runner.py:234} INFO - Task exited with return code 1
[2024-04-06T17:01:47.303+0000] {taskinstance.py:3312} INFO - 0 downstream tasks scheduled from follow-on schedule check
