[2024-04-02T00:43:48.675+0000] {processor.py:161} INFO - Started process (PID=72) to work on /opt/airflow/dags/download_NASA_API_dags.py
[2024-04-02T00:43:48.676+0000] {processor.py:830} INFO - Processing file /opt/airflow/dags/download_NASA_API_dags.py for tasks to queue
[2024-04-02T00:43:48.678+0000] {logging_mixin.py:188} INFO - [2024-04-02T00:43:48.678+0000] {dagbag.py:540} INFO - Filling up the DagBag from /opt/airflow/dags/download_NASA_API_dags.py
[2024-04-02T00:43:49.306+0000] {logging_mixin.py:188} INFO - [2024-04-02T00:43:49.300+0000] {dagbag.py:350} ERROR - Failed to import: /opt/airflow/dags/download_NASA_API_dags.py
Traceback (most recent call last):
  File "/home/airflow/.local/lib/python3.8/site-packages/airflow/models/dagbag.py", line 346, in parse
    loader.exec_module(new_module)
  File "<frozen importlib._bootstrap_external>", line 843, in exec_module
  File "<frozen importlib._bootstrap>", line 219, in _call_with_frames_removed
  File "/opt/airflow/dags/download_NASA_API_dags.py", line 15, in <module>
    os.makedirs(output_estado_raw, exist_ok=True)
  File "/usr/local/lib/python3.8/os.py", line 213, in makedirs
    makedirs(head, exist_ok=exist_ok)
  File "/usr/local/lib/python3.8/os.py", line 213, in makedirs
    makedirs(head, exist_ok=exist_ok)
  File "/usr/local/lib/python3.8/os.py", line 223, in makedirs
    mkdir(name, mode)
PermissionError: [Errno 13] Permission denied: '/usr/local/airflow'
[2024-04-02T00:43:49.306+0000] {processor.py:842} WARNING - No viable dags retrieved from /opt/airflow/dags/download_NASA_API_dags.py
[2024-04-02T00:43:49.351+0000] {processor.py:183} INFO - Processing /opt/airflow/dags/download_NASA_API_dags.py took 0.680 seconds
[2024-04-02T00:44:19.558+0000] {processor.py:161} INFO - Started process (PID=97) to work on /opt/airflow/dags/download_NASA_API_dags.py
[2024-04-02T00:44:19.560+0000] {processor.py:830} INFO - Processing file /opt/airflow/dags/download_NASA_API_dags.py for tasks to queue
[2024-04-02T00:44:19.562+0000] {logging_mixin.py:188} INFO - [2024-04-02T00:44:19.561+0000] {dagbag.py:540} INFO - Filling up the DagBag from /opt/airflow/dags/download_NASA_API_dags.py
[2024-04-02T00:44:20.298+0000] {logging_mixin.py:188} INFO - [2024-04-02T00:44:20.289+0000] {dagbag.py:350} ERROR - Failed to import: /opt/airflow/dags/download_NASA_API_dags.py
Traceback (most recent call last):
  File "/home/airflow/.local/lib/python3.8/site-packages/airflow/models/dagbag.py", line 346, in parse
    loader.exec_module(new_module)
  File "<frozen importlib._bootstrap_external>", line 843, in exec_module
  File "<frozen importlib._bootstrap>", line 219, in _call_with_frames_removed
  File "/opt/airflow/dags/download_NASA_API_dags.py", line 15, in <module>
    os.makedirs(output_estado_raw, exist_ok=True)
  File "/usr/local/lib/python3.8/os.py", line 213, in makedirs
    makedirs(head, exist_ok=exist_ok)
  File "/usr/local/lib/python3.8/os.py", line 213, in makedirs
    makedirs(head, exist_ok=exist_ok)
  File "/usr/local/lib/python3.8/os.py", line 223, in makedirs
    mkdir(name, mode)
PermissionError: [Errno 13] Permission denied: '/usr/local/airflow'
[2024-04-02T00:44:20.298+0000] {processor.py:842} WARNING - No viable dags retrieved from /opt/airflow/dags/download_NASA_API_dags.py
[2024-04-02T00:44:20.363+0000] {processor.py:183} INFO - Processing /opt/airflow/dags/download_NASA_API_dags.py took 0.810 seconds
[2024-04-02T00:44:51.579+0000] {processor.py:161} INFO - Started process (PID=100) to work on /opt/airflow/dags/download_NASA_API_dags.py
[2024-04-02T00:44:51.581+0000] {processor.py:830} INFO - Processing file /opt/airflow/dags/download_NASA_API_dags.py for tasks to queue
[2024-04-02T00:44:51.583+0000] {logging_mixin.py:188} INFO - [2024-04-02T00:44:51.582+0000] {dagbag.py:540} INFO - Filling up the DagBag from /opt/airflow/dags/download_NASA_API_dags.py
[2024-04-02T00:44:52.275+0000] {logging_mixin.py:188} INFO - [2024-04-02T00:44:52.267+0000] {dagbag.py:350} ERROR - Failed to import: /opt/airflow/dags/download_NASA_API_dags.py
Traceback (most recent call last):
  File "/home/airflow/.local/lib/python3.8/site-packages/airflow/models/dagbag.py", line 346, in parse
    loader.exec_module(new_module)
  File "<frozen importlib._bootstrap_external>", line 843, in exec_module
  File "<frozen importlib._bootstrap>", line 219, in _call_with_frames_removed
  File "/opt/airflow/dags/download_NASA_API_dags.py", line 15, in <module>
    os.makedirs(output_estado_raw, exist_ok=True)
  File "/usr/local/lib/python3.8/os.py", line 213, in makedirs
    makedirs(head, exist_ok=exist_ok)
  File "/usr/local/lib/python3.8/os.py", line 213, in makedirs
    makedirs(head, exist_ok=exist_ok)
  File "/usr/local/lib/python3.8/os.py", line 223, in makedirs
    mkdir(name, mode)
PermissionError: [Errno 13] Permission denied: '/usr/local/airflow'
[2024-04-02T00:44:52.275+0000] {processor.py:842} WARNING - No viable dags retrieved from /opt/airflow/dags/download_NASA_API_dags.py
[2024-04-02T00:44:52.332+0000] {processor.py:183} INFO - Processing /opt/airflow/dags/download_NASA_API_dags.py took 0.756 seconds
[2024-04-02T00:45:23.159+0000] {processor.py:161} INFO - Started process (PID=103) to work on /opt/airflow/dags/download_NASA_API_dags.py
[2024-04-02T00:45:23.160+0000] {processor.py:830} INFO - Processing file /opt/airflow/dags/download_NASA_API_dags.py for tasks to queue
[2024-04-02T00:45:23.162+0000] {logging_mixin.py:188} INFO - [2024-04-02T00:45:23.161+0000] {dagbag.py:540} INFO - Filling up the DagBag from /opt/airflow/dags/download_NASA_API_dags.py
[2024-04-02T00:45:23.852+0000] {logging_mixin.py:188} INFO - [2024-04-02T00:45:23.844+0000] {dagbag.py:350} ERROR - Failed to import: /opt/airflow/dags/download_NASA_API_dags.py
Traceback (most recent call last):
  File "/home/airflow/.local/lib/python3.8/site-packages/airflow/models/dagbag.py", line 346, in parse
    loader.exec_module(new_module)
  File "<frozen importlib._bootstrap_external>", line 843, in exec_module
  File "<frozen importlib._bootstrap>", line 219, in _call_with_frames_removed
  File "/opt/airflow/dags/download_NASA_API_dags.py", line 15, in <module>
    os.makedirs(output_estado_raw, exist_ok=True)
  File "/usr/local/lib/python3.8/os.py", line 213, in makedirs
    makedirs(head, exist_ok=exist_ok)
  File "/usr/local/lib/python3.8/os.py", line 213, in makedirs
    makedirs(head, exist_ok=exist_ok)
  File "/usr/local/lib/python3.8/os.py", line 223, in makedirs
    mkdir(name, mode)
PermissionError: [Errno 13] Permission denied: '/usr/local/airflow'
[2024-04-02T00:45:23.853+0000] {processor.py:842} WARNING - No viable dags retrieved from /opt/airflow/dags/download_NASA_API_dags.py
[2024-04-02T00:45:23.913+0000] {processor.py:183} INFO - Processing /opt/airflow/dags/download_NASA_API_dags.py took 0.758 seconds
[2024-04-02T00:45:54.765+0000] {processor.py:161} INFO - Started process (PID=106) to work on /opt/airflow/dags/download_NASA_API_dags.py
[2024-04-02T00:45:54.766+0000] {processor.py:830} INFO - Processing file /opt/airflow/dags/download_NASA_API_dags.py for tasks to queue
[2024-04-02T00:45:54.768+0000] {logging_mixin.py:188} INFO - [2024-04-02T00:45:54.767+0000] {dagbag.py:540} INFO - Filling up the DagBag from /opt/airflow/dags/download_NASA_API_dags.py
[2024-04-02T00:45:55.495+0000] {logging_mixin.py:188} INFO - [2024-04-02T00:45:55.481+0000] {dagbag.py:350} ERROR - Failed to import: /opt/airflow/dags/download_NASA_API_dags.py
Traceback (most recent call last):
  File "/home/airflow/.local/lib/python3.8/site-packages/airflow/models/dagbag.py", line 346, in parse
    loader.exec_module(new_module)
  File "<frozen importlib._bootstrap_external>", line 843, in exec_module
  File "<frozen importlib._bootstrap>", line 219, in _call_with_frames_removed
  File "/opt/airflow/dags/download_NASA_API_dags.py", line 15, in <module>
    os.makedirs(output_estado_raw, exist_ok=True)
  File "/usr/local/lib/python3.8/os.py", line 213, in makedirs
    makedirs(head, exist_ok=exist_ok)
  File "/usr/local/lib/python3.8/os.py", line 213, in makedirs
    makedirs(head, exist_ok=exist_ok)
  File "/usr/local/lib/python3.8/os.py", line 223, in makedirs
    mkdir(name, mode)
PermissionError: [Errno 13] Permission denied: '/usr/local/airflow'
[2024-04-02T00:45:55.496+0000] {processor.py:842} WARNING - No viable dags retrieved from /opt/airflow/dags/download_NASA_API_dags.py
[2024-04-02T00:45:55.567+0000] {processor.py:183} INFO - Processing /opt/airflow/dags/download_NASA_API_dags.py took 0.807 seconds
[2024-04-02T00:46:26.326+0000] {processor.py:161} INFO - Started process (PID=109) to work on /opt/airflow/dags/download_NASA_API_dags.py
[2024-04-02T00:46:26.328+0000] {processor.py:830} INFO - Processing file /opt/airflow/dags/download_NASA_API_dags.py for tasks to queue
[2024-04-02T00:46:26.329+0000] {logging_mixin.py:188} INFO - [2024-04-02T00:46:26.329+0000] {dagbag.py:540} INFO - Filling up the DagBag from /opt/airflow/dags/download_NASA_API_dags.py
[2024-04-02T00:46:27.086+0000] {logging_mixin.py:188} INFO - [2024-04-02T00:46:27.077+0000] {dagbag.py:350} ERROR - Failed to import: /opt/airflow/dags/download_NASA_API_dags.py
Traceback (most recent call last):
  File "/home/airflow/.local/lib/python3.8/site-packages/airflow/models/dagbag.py", line 346, in parse
    loader.exec_module(new_module)
  File "<frozen importlib._bootstrap_external>", line 843, in exec_module
  File "<frozen importlib._bootstrap>", line 219, in _call_with_frames_removed
  File "/opt/airflow/dags/download_NASA_API_dags.py", line 15, in <module>
    os.makedirs(output_estado_raw, exist_ok=True)
  File "/usr/local/lib/python3.8/os.py", line 213, in makedirs
    makedirs(head, exist_ok=exist_ok)
  File "/usr/local/lib/python3.8/os.py", line 213, in makedirs
    makedirs(head, exist_ok=exist_ok)
  File "/usr/local/lib/python3.8/os.py", line 223, in makedirs
    mkdir(name, mode)
PermissionError: [Errno 13] Permission denied: '/usr/local/airflow'
[2024-04-02T00:46:27.088+0000] {processor.py:842} WARNING - No viable dags retrieved from /opt/airflow/dags/download_NASA_API_dags.py
[2024-04-02T00:46:27.471+0000] {processor.py:183} INFO - Processing /opt/airflow/dags/download_NASA_API_dags.py took 1.148 seconds
[2024-04-02T00:46:58.243+0000] {processor.py:161} INFO - Started process (PID=112) to work on /opt/airflow/dags/download_NASA_API_dags.py
[2024-04-02T00:46:58.244+0000] {processor.py:830} INFO - Processing file /opt/airflow/dags/download_NASA_API_dags.py for tasks to queue
[2024-04-02T00:46:58.246+0000] {logging_mixin.py:188} INFO - [2024-04-02T00:46:58.246+0000] {dagbag.py:540} INFO - Filling up the DagBag from /opt/airflow/dags/download_NASA_API_dags.py
[2024-04-02T00:46:58.923+0000] {logging_mixin.py:188} INFO - [2024-04-02T00:46:58.915+0000] {dagbag.py:350} ERROR - Failed to import: /opt/airflow/dags/download_NASA_API_dags.py
Traceback (most recent call last):
  File "/home/airflow/.local/lib/python3.8/site-packages/airflow/models/dagbag.py", line 346, in parse
    loader.exec_module(new_module)
  File "<frozen importlib._bootstrap_external>", line 843, in exec_module
  File "<frozen importlib._bootstrap>", line 219, in _call_with_frames_removed
  File "/opt/airflow/dags/download_NASA_API_dags.py", line 15, in <module>
    os.makedirs(output_estado_raw, exist_ok=True)
  File "/usr/local/lib/python3.8/os.py", line 213, in makedirs
    makedirs(head, exist_ok=exist_ok)
  File "/usr/local/lib/python3.8/os.py", line 213, in makedirs
    makedirs(head, exist_ok=exist_ok)
  File "/usr/local/lib/python3.8/os.py", line 223, in makedirs
    mkdir(name, mode)
PermissionError: [Errno 13] Permission denied: '/usr/local/airflow'
[2024-04-02T00:46:58.924+0000] {processor.py:842} WARNING - No viable dags retrieved from /opt/airflow/dags/download_NASA_API_dags.py
[2024-04-02T00:46:58.982+0000] {processor.py:183} INFO - Processing /opt/airflow/dags/download_NASA_API_dags.py took 0.744 seconds
[2024-04-02T00:47:29.539+0000] {processor.py:161} INFO - Started process (PID=115) to work on /opt/airflow/dags/download_NASA_API_dags.py
[2024-04-02T00:47:29.541+0000] {processor.py:830} INFO - Processing file /opt/airflow/dags/download_NASA_API_dags.py for tasks to queue
[2024-04-02T00:47:29.542+0000] {logging_mixin.py:188} INFO - [2024-04-02T00:47:29.542+0000] {dagbag.py:540} INFO - Filling up the DagBag from /opt/airflow/dags/download_NASA_API_dags.py
[2024-04-02T00:47:30.197+0000] {logging_mixin.py:188} INFO - [2024-04-02T00:47:30.189+0000] {dagbag.py:350} ERROR - Failed to import: /opt/airflow/dags/download_NASA_API_dags.py
Traceback (most recent call last):
  File "/home/airflow/.local/lib/python3.8/site-packages/airflow/models/dagbag.py", line 346, in parse
    loader.exec_module(new_module)
  File "<frozen importlib._bootstrap_external>", line 843, in exec_module
  File "<frozen importlib._bootstrap>", line 219, in _call_with_frames_removed
  File "/opt/airflow/dags/download_NASA_API_dags.py", line 15, in <module>
    os.makedirs(output_estado_raw, exist_ok=True)
  File "/usr/local/lib/python3.8/os.py", line 213, in makedirs
    makedirs(head, exist_ok=exist_ok)
  File "/usr/local/lib/python3.8/os.py", line 213, in makedirs
    makedirs(head, exist_ok=exist_ok)
  File "/usr/local/lib/python3.8/os.py", line 223, in makedirs
    mkdir(name, mode)
PermissionError: [Errno 13] Permission denied: '/usr/local/airflow'
[2024-04-02T00:47:30.198+0000] {processor.py:842} WARNING - No viable dags retrieved from /opt/airflow/dags/download_NASA_API_dags.py
[2024-04-02T00:47:30.259+0000] {processor.py:183} INFO - Processing /opt/airflow/dags/download_NASA_API_dags.py took 0.723 seconds
[2024-04-02T00:48:00.773+0000] {processor.py:161} INFO - Started process (PID=118) to work on /opt/airflow/dags/download_NASA_API_dags.py
[2024-04-02T00:48:00.774+0000] {processor.py:830} INFO - Processing file /opt/airflow/dags/download_NASA_API_dags.py for tasks to queue
[2024-04-02T00:48:00.776+0000] {logging_mixin.py:188} INFO - [2024-04-02T00:48:00.775+0000] {dagbag.py:540} INFO - Filling up the DagBag from /opt/airflow/dags/download_NASA_API_dags.py
[2024-04-02T00:48:01.459+0000] {logging_mixin.py:188} INFO - [2024-04-02T00:48:01.451+0000] {dagbag.py:350} ERROR - Failed to import: /opt/airflow/dags/download_NASA_API_dags.py
Traceback (most recent call last):
  File "/home/airflow/.local/lib/python3.8/site-packages/airflow/models/dagbag.py", line 346, in parse
    loader.exec_module(new_module)
  File "<frozen importlib._bootstrap_external>", line 843, in exec_module
  File "<frozen importlib._bootstrap>", line 219, in _call_with_frames_removed
  File "/opt/airflow/dags/download_NASA_API_dags.py", line 15, in <module>
    os.makedirs(output_estado_raw, exist_ok=True)
  File "/usr/local/lib/python3.8/os.py", line 213, in makedirs
    makedirs(head, exist_ok=exist_ok)
  File "/usr/local/lib/python3.8/os.py", line 213, in makedirs
    makedirs(head, exist_ok=exist_ok)
  File "/usr/local/lib/python3.8/os.py", line 223, in makedirs
    mkdir(name, mode)
PermissionError: [Errno 13] Permission denied: '/usr/local/airflow'
[2024-04-02T00:48:01.460+0000] {processor.py:842} WARNING - No viable dags retrieved from /opt/airflow/dags/download_NASA_API_dags.py
[2024-04-02T00:48:01.519+0000] {processor.py:183} INFO - Processing /opt/airflow/dags/download_NASA_API_dags.py took 0.750 seconds
[2024-04-02T00:56:38.902+0000] {processor.py:161} INFO - Started process (PID=72) to work on /opt/airflow/dags/download_NASA_API_dags.py
[2024-04-02T00:56:38.903+0000] {processor.py:830} INFO - Processing file /opt/airflow/dags/download_NASA_API_dags.py for tasks to queue
[2024-04-02T00:56:38.904+0000] {logging_mixin.py:188} INFO - [2024-04-02T00:56:38.904+0000] {dagbag.py:540} INFO - Filling up the DagBag from /opt/airflow/dags/download_NASA_API_dags.py
[2024-04-02T00:56:39.501+0000] {logging_mixin.py:188} INFO - [2024-04-02T00:56:39.495+0000] {dagbag.py:350} ERROR - Failed to import: /opt/airflow/dags/download_NASA_API_dags.py
Traceback (most recent call last):
  File "/home/airflow/.local/lib/python3.8/site-packages/airflow/models/dagbag.py", line 346, in parse
    loader.exec_module(new_module)
  File "<frozen importlib._bootstrap_external>", line 843, in exec_module
  File "<frozen importlib._bootstrap>", line 219, in _call_with_frames_removed
  File "/opt/airflow/dags/download_NASA_API_dags.py", line 15, in <module>
    os.makedirs(output_estado_raw, exist_ok=True)
  File "/usr/local/lib/python3.8/os.py", line 213, in makedirs
    makedirs(head, exist_ok=exist_ok)
  File "/usr/local/lib/python3.8/os.py", line 213, in makedirs
    makedirs(head, exist_ok=exist_ok)
  File "/usr/local/lib/python3.8/os.py", line 223, in makedirs
    mkdir(name, mode)
PermissionError: [Errno 13] Permission denied: '/usr/local/airflow'
[2024-04-02T00:56:39.502+0000] {processor.py:842} WARNING - No viable dags retrieved from /opt/airflow/dags/download_NASA_API_dags.py
[2024-04-02T00:56:39.544+0000] {processor.py:183} INFO - Processing /opt/airflow/dags/download_NASA_API_dags.py took 0.646 seconds
[2024-04-02T00:57:10.515+0000] {processor.py:161} INFO - Started process (PID=97) to work on /opt/airflow/dags/download_NASA_API_dags.py
[2024-04-02T00:57:10.517+0000] {processor.py:830} INFO - Processing file /opt/airflow/dags/download_NASA_API_dags.py for tasks to queue
[2024-04-02T00:57:10.519+0000] {logging_mixin.py:188} INFO - [2024-04-02T00:57:10.519+0000] {dagbag.py:540} INFO - Filling up the DagBag from /opt/airflow/dags/download_NASA_API_dags.py
[2024-04-02T00:57:11.212+0000] {logging_mixin.py:188} INFO - [2024-04-02T00:57:11.205+0000] {dagbag.py:350} ERROR - Failed to import: /opt/airflow/dags/download_NASA_API_dags.py
Traceback (most recent call last):
  File "/home/airflow/.local/lib/python3.8/site-packages/airflow/models/dagbag.py", line 346, in parse
    loader.exec_module(new_module)
  File "<frozen importlib._bootstrap_external>", line 843, in exec_module
  File "<frozen importlib._bootstrap>", line 219, in _call_with_frames_removed
  File "/opt/airflow/dags/download_NASA_API_dags.py", line 15, in <module>
    os.makedirs(output_estado_raw, exist_ok=True)
  File "/usr/local/lib/python3.8/os.py", line 213, in makedirs
    makedirs(head, exist_ok=exist_ok)
  File "/usr/local/lib/python3.8/os.py", line 213, in makedirs
    makedirs(head, exist_ok=exist_ok)
  File "/usr/local/lib/python3.8/os.py", line 223, in makedirs
    mkdir(name, mode)
PermissionError: [Errno 13] Permission denied: '/usr/local/airflow'
[2024-04-02T00:57:11.214+0000] {processor.py:842} WARNING - No viable dags retrieved from /opt/airflow/dags/download_NASA_API_dags.py
[2024-04-02T00:57:11.279+0000] {processor.py:183} INFO - Processing /opt/airflow/dags/download_NASA_API_dags.py took 0.770 seconds
[2024-04-02T00:57:41.632+0000] {processor.py:161} INFO - Started process (PID=100) to work on /opt/airflow/dags/download_NASA_API_dags.py
[2024-04-02T00:57:41.633+0000] {processor.py:830} INFO - Processing file /opt/airflow/dags/download_NASA_API_dags.py for tasks to queue
[2024-04-02T00:57:41.635+0000] {logging_mixin.py:188} INFO - [2024-04-02T00:57:41.634+0000] {dagbag.py:540} INFO - Filling up the DagBag from /opt/airflow/dags/download_NASA_API_dags.py
[2024-04-02T00:57:42.186+0000] {logging_mixin.py:188} INFO - [2024-04-02T00:57:42.180+0000] {dagbag.py:350} ERROR - Failed to import: /opt/airflow/dags/download_NASA_API_dags.py
Traceback (most recent call last):
  File "/home/airflow/.local/lib/python3.8/site-packages/airflow/models/dagbag.py", line 346, in parse
    loader.exec_module(new_module)
  File "<frozen importlib._bootstrap_external>", line 843, in exec_module
  File "<frozen importlib._bootstrap>", line 219, in _call_with_frames_removed
  File "/opt/airflow/dags/download_NASA_API_dags.py", line 15, in <module>
    os.makedirs(output_estado_raw, exist_ok=True)
  File "/usr/local/lib/python3.8/os.py", line 213, in makedirs
    makedirs(head, exist_ok=exist_ok)
  File "/usr/local/lib/python3.8/os.py", line 213, in makedirs
    makedirs(head, exist_ok=exist_ok)
  File "/usr/local/lib/python3.8/os.py", line 223, in makedirs
    mkdir(name, mode)
PermissionError: [Errno 13] Permission denied: '/usr/local/airflow'
[2024-04-02T00:57:42.186+0000] {processor.py:842} WARNING - No viable dags retrieved from /opt/airflow/dags/download_NASA_API_dags.py
[2024-04-02T00:57:42.231+0000] {processor.py:183} INFO - Processing /opt/airflow/dags/download_NASA_API_dags.py took 0.603 seconds
[2024-04-02T00:58:12.551+0000] {processor.py:161} INFO - Started process (PID=103) to work on /opt/airflow/dags/download_NASA_API_dags.py
[2024-04-02T00:58:12.553+0000] {processor.py:830} INFO - Processing file /opt/airflow/dags/download_NASA_API_dags.py for tasks to queue
[2024-04-02T00:58:12.554+0000] {logging_mixin.py:188} INFO - [2024-04-02T00:58:12.554+0000] {dagbag.py:540} INFO - Filling up the DagBag from /opt/airflow/dags/download_NASA_API_dags.py
[2024-04-02T00:58:13.309+0000] {logging_mixin.py:188} INFO - [2024-04-02T00:58:13.301+0000] {dagbag.py:350} ERROR - Failed to import: /opt/airflow/dags/download_NASA_API_dags.py
Traceback (most recent call last):
  File "/home/airflow/.local/lib/python3.8/site-packages/airflow/models/dagbag.py", line 346, in parse
    loader.exec_module(new_module)
  File "<frozen importlib._bootstrap_external>", line 843, in exec_module
  File "<frozen importlib._bootstrap>", line 219, in _call_with_frames_removed
  File "/opt/airflow/dags/download_NASA_API_dags.py", line 15, in <module>
    os.makedirs(output_estado_raw, exist_ok=True)
  File "/usr/local/lib/python3.8/os.py", line 213, in makedirs
    makedirs(head, exist_ok=exist_ok)
  File "/usr/local/lib/python3.8/os.py", line 213, in makedirs
    makedirs(head, exist_ok=exist_ok)
  File "/usr/local/lib/python3.8/os.py", line 223, in makedirs
    mkdir(name, mode)
PermissionError: [Errno 13] Permission denied: '/usr/local/airflow'
[2024-04-02T00:58:13.310+0000] {processor.py:842} WARNING - No viable dags retrieved from /opt/airflow/dags/download_NASA_API_dags.py
[2024-04-02T00:58:13.364+0000] {processor.py:183} INFO - Processing /opt/airflow/dags/download_NASA_API_dags.py took 0.816 seconds
[2024-04-02T00:58:43.665+0000] {processor.py:161} INFO - Started process (PID=106) to work on /opt/airflow/dags/download_NASA_API_dags.py
[2024-04-02T00:58:43.670+0000] {processor.py:830} INFO - Processing file /opt/airflow/dags/download_NASA_API_dags.py for tasks to queue
[2024-04-02T00:58:43.673+0000] {logging_mixin.py:188} INFO - [2024-04-02T00:58:43.672+0000] {dagbag.py:540} INFO - Filling up the DagBag from /opt/airflow/dags/download_NASA_API_dags.py
[2024-04-02T00:58:44.445+0000] {logging_mixin.py:188} INFO - [2024-04-02T00:58:44.436+0000] {dagbag.py:350} ERROR - Failed to import: /opt/airflow/dags/download_NASA_API_dags.py
Traceback (most recent call last):
  File "/home/airflow/.local/lib/python3.8/site-packages/airflow/models/dagbag.py", line 346, in parse
    loader.exec_module(new_module)
  File "<frozen importlib._bootstrap_external>", line 843, in exec_module
  File "<frozen importlib._bootstrap>", line 219, in _call_with_frames_removed
  File "/opt/airflow/dags/download_NASA_API_dags.py", line 15, in <module>
    os.makedirs(output_estado_raw, exist_ok=True)
  File "/usr/local/lib/python3.8/os.py", line 213, in makedirs
    makedirs(head, exist_ok=exist_ok)
  File "/usr/local/lib/python3.8/os.py", line 213, in makedirs
    makedirs(head, exist_ok=exist_ok)
  File "/usr/local/lib/python3.8/os.py", line 223, in makedirs
    mkdir(name, mode)
PermissionError: [Errno 13] Permission denied: '/usr/local/airflow'
[2024-04-02T00:58:44.446+0000] {processor.py:842} WARNING - No viable dags retrieved from /opt/airflow/dags/download_NASA_API_dags.py
[2024-04-02T00:58:44.514+0000] {processor.py:183} INFO - Processing /opt/airflow/dags/download_NASA_API_dags.py took 0.853 seconds
[2024-04-02T00:59:14.777+0000] {processor.py:161} INFO - Started process (PID=109) to work on /opt/airflow/dags/download_NASA_API_dags.py
[2024-04-02T00:59:14.779+0000] {processor.py:830} INFO - Processing file /opt/airflow/dags/download_NASA_API_dags.py for tasks to queue
[2024-04-02T00:59:14.780+0000] {logging_mixin.py:188} INFO - [2024-04-02T00:59:14.780+0000] {dagbag.py:540} INFO - Filling up the DagBag from /opt/airflow/dags/download_NASA_API_dags.py
[2024-04-02T00:59:15.400+0000] {logging_mixin.py:188} INFO - [2024-04-02T00:59:15.391+0000] {dagbag.py:350} ERROR - Failed to import: /opt/airflow/dags/download_NASA_API_dags.py
Traceback (most recent call last):
  File "/home/airflow/.local/lib/python3.8/site-packages/airflow/models/dagbag.py", line 346, in parse
    loader.exec_module(new_module)
  File "<frozen importlib._bootstrap_external>", line 843, in exec_module
  File "<frozen importlib._bootstrap>", line 219, in _call_with_frames_removed
  File "/opt/airflow/dags/download_NASA_API_dags.py", line 15, in <module>
    os.makedirs(output_estado_raw, exist_ok=True)
  File "/usr/local/lib/python3.8/os.py", line 213, in makedirs
    makedirs(head, exist_ok=exist_ok)
  File "/usr/local/lib/python3.8/os.py", line 213, in makedirs
    makedirs(head, exist_ok=exist_ok)
  File "/usr/local/lib/python3.8/os.py", line 223, in makedirs
    mkdir(name, mode)
PermissionError: [Errno 13] Permission denied: '/usr/local/airflow'
[2024-04-02T00:59:15.401+0000] {processor.py:842} WARNING - No viable dags retrieved from /opt/airflow/dags/download_NASA_API_dags.py
[2024-04-02T00:59:15.457+0000] {processor.py:183} INFO - Processing /opt/airflow/dags/download_NASA_API_dags.py took 0.683 seconds
[2024-04-02T00:59:45.879+0000] {processor.py:161} INFO - Started process (PID=112) to work on /opt/airflow/dags/download_NASA_API_dags.py
[2024-04-02T00:59:45.880+0000] {processor.py:830} INFO - Processing file /opt/airflow/dags/download_NASA_API_dags.py for tasks to queue
[2024-04-02T00:59:45.882+0000] {logging_mixin.py:188} INFO - [2024-04-02T00:59:45.881+0000] {dagbag.py:540} INFO - Filling up the DagBag from /opt/airflow/dags/download_NASA_API_dags.py
[2024-04-02T00:59:46.580+0000] {logging_mixin.py:188} INFO - [2024-04-02T00:59:46.573+0000] {dagbag.py:350} ERROR - Failed to import: /opt/airflow/dags/download_NASA_API_dags.py
Traceback (most recent call last):
  File "/home/airflow/.local/lib/python3.8/site-packages/airflow/models/dagbag.py", line 346, in parse
    loader.exec_module(new_module)
  File "<frozen importlib._bootstrap_external>", line 843, in exec_module
  File "<frozen importlib._bootstrap>", line 219, in _call_with_frames_removed
  File "/opt/airflow/dags/download_NASA_API_dags.py", line 15, in <module>
    os.makedirs(output_estado_raw, exist_ok=True)
  File "/usr/local/lib/python3.8/os.py", line 213, in makedirs
    makedirs(head, exist_ok=exist_ok)
  File "/usr/local/lib/python3.8/os.py", line 213, in makedirs
    makedirs(head, exist_ok=exist_ok)
  File "/usr/local/lib/python3.8/os.py", line 223, in makedirs
    mkdir(name, mode)
PermissionError: [Errno 13] Permission denied: '/usr/local/airflow'
[2024-04-02T00:59:46.581+0000] {processor.py:842} WARNING - No viable dags retrieved from /opt/airflow/dags/download_NASA_API_dags.py
[2024-04-02T00:59:46.640+0000] {processor.py:183} INFO - Processing /opt/airflow/dags/download_NASA_API_dags.py took 0.764 seconds
[2024-04-02T01:00:17.112+0000] {processor.py:161} INFO - Started process (PID=115) to work on /opt/airflow/dags/download_NASA_API_dags.py
[2024-04-02T01:00:17.113+0000] {processor.py:830} INFO - Processing file /opt/airflow/dags/download_NASA_API_dags.py for tasks to queue
[2024-04-02T01:00:17.114+0000] {logging_mixin.py:188} INFO - [2024-04-02T01:00:17.114+0000] {dagbag.py:540} INFO - Filling up the DagBag from /opt/airflow/dags/download_NASA_API_dags.py
[2024-04-02T01:00:17.787+0000] {logging_mixin.py:188} INFO - [2024-04-02T01:00:17.779+0000] {dagbag.py:350} ERROR - Failed to import: /opt/airflow/dags/download_NASA_API_dags.py
Traceback (most recent call last):
  File "/home/airflow/.local/lib/python3.8/site-packages/airflow/models/dagbag.py", line 346, in parse
    loader.exec_module(new_module)
  File "<frozen importlib._bootstrap_external>", line 843, in exec_module
  File "<frozen importlib._bootstrap>", line 219, in _call_with_frames_removed
  File "/opt/airflow/dags/download_NASA_API_dags.py", line 15, in <module>
    os.makedirs(output_estado_raw, exist_ok=True)
  File "/usr/local/lib/python3.8/os.py", line 213, in makedirs
    makedirs(head, exist_ok=exist_ok)
  File "/usr/local/lib/python3.8/os.py", line 213, in makedirs
    makedirs(head, exist_ok=exist_ok)
  File "/usr/local/lib/python3.8/os.py", line 223, in makedirs
    mkdir(name, mode)
PermissionError: [Errno 13] Permission denied: '/usr/local/airflow'
[2024-04-02T01:00:17.788+0000] {processor.py:842} WARNING - No viable dags retrieved from /opt/airflow/dags/download_NASA_API_dags.py
[2024-04-02T01:00:17.846+0000] {processor.py:183} INFO - Processing /opt/airflow/dags/download_NASA_API_dags.py took 0.738 seconds
[2024-04-02T01:00:48.354+0000] {processor.py:161} INFO - Started process (PID=118) to work on /opt/airflow/dags/download_NASA_API_dags.py
[2024-04-02T01:00:48.355+0000] {processor.py:830} INFO - Processing file /opt/airflow/dags/download_NASA_API_dags.py for tasks to queue
[2024-04-02T01:00:48.357+0000] {logging_mixin.py:188} INFO - [2024-04-02T01:00:48.357+0000] {dagbag.py:540} INFO - Filling up the DagBag from /opt/airflow/dags/download_NASA_API_dags.py
[2024-04-02T01:00:49.118+0000] {logging_mixin.py:188} INFO - [2024-04-02T01:00:49.111+0000] {dagbag.py:350} ERROR - Failed to import: /opt/airflow/dags/download_NASA_API_dags.py
Traceback (most recent call last):
  File "/home/airflow/.local/lib/python3.8/site-packages/airflow/models/dagbag.py", line 346, in parse
    loader.exec_module(new_module)
  File "<frozen importlib._bootstrap_external>", line 843, in exec_module
  File "<frozen importlib._bootstrap>", line 219, in _call_with_frames_removed
  File "/opt/airflow/dags/download_NASA_API_dags.py", line 15, in <module>
    os.makedirs(output_estado_raw, exist_ok=True)
  File "/usr/local/lib/python3.8/os.py", line 213, in makedirs
    makedirs(head, exist_ok=exist_ok)
  File "/usr/local/lib/python3.8/os.py", line 213, in makedirs
    makedirs(head, exist_ok=exist_ok)
  File "/usr/local/lib/python3.8/os.py", line 223, in makedirs
    mkdir(name, mode)
PermissionError: [Errno 13] Permission denied: '/usr/local/airflow'
[2024-04-02T01:00:49.118+0000] {processor.py:842} WARNING - No viable dags retrieved from /opt/airflow/dags/download_NASA_API_dags.py
[2024-04-02T01:00:49.169+0000] {processor.py:183} INFO - Processing /opt/airflow/dags/download_NASA_API_dags.py took 0.819 seconds
[2024-04-02T01:03:02.166+0000] {processor.py:161} INFO - Started process (PID=123) to work on /opt/airflow/dags/download_NASA_API_dags.py
[2024-04-02T01:03:02.169+0000] {processor.py:830} INFO - Processing file /opt/airflow/dags/download_NASA_API_dags.py for tasks to queue
[2024-04-02T01:03:02.171+0000] {logging_mixin.py:188} INFO - [2024-04-02T01:03:02.170+0000] {dagbag.py:540} INFO - Filling up the DagBag from /opt/airflow/dags/download_NASA_API_dags.py
[2024-04-02T01:03:03.104+0000] {logging_mixin.py:188} INFO - [2024-04-02T01:03:03.095+0000] {dagbag.py:350} ERROR - Failed to import: /opt/airflow/dags/download_NASA_API_dags.py
Traceback (most recent call last):
  File "/home/airflow/.local/lib/python3.8/site-packages/airflow/models/dagbag.py", line 346, in parse
    loader.exec_module(new_module)
  File "<frozen importlib._bootstrap_external>", line 843, in exec_module
  File "<frozen importlib._bootstrap>", line 219, in _call_with_frames_removed
  File "/opt/airflow/dags/download_NASA_API_dags.py", line 15, in <module>
    os.makedirs(output_estado_raw, exist_ok=True)
  File "/usr/local/lib/python3.8/os.py", line 213, in makedirs
    makedirs(head, exist_ok=exist_ok)
  File "/usr/local/lib/python3.8/os.py", line 213, in makedirs
    makedirs(head, exist_ok=exist_ok)
  File "/usr/local/lib/python3.8/os.py", line 223, in makedirs
    mkdir(name, mode)
PermissionError: [Errno 13] Permission denied: '/usr/local/airflow'
[2024-04-02T01:03:03.105+0000] {processor.py:842} WARNING - No viable dags retrieved from /opt/airflow/dags/download_NASA_API_dags.py
[2024-04-02T01:03:03.164+0000] {processor.py:183} INFO - Processing /opt/airflow/dags/download_NASA_API_dags.py took 1.003 seconds
[2024-04-02T01:03:33.699+0000] {processor.py:161} INFO - Started process (PID=132) to work on /opt/airflow/dags/download_NASA_API_dags.py
[2024-04-02T01:03:33.700+0000] {processor.py:830} INFO - Processing file /opt/airflow/dags/download_NASA_API_dags.py for tasks to queue
[2024-04-02T01:03:33.702+0000] {logging_mixin.py:188} INFO - [2024-04-02T01:03:33.701+0000] {dagbag.py:540} INFO - Filling up the DagBag from /opt/airflow/dags/download_NASA_API_dags.py
[2024-04-02T01:03:34.426+0000] {logging_mixin.py:188} INFO - [2024-04-02T01:03:34.416+0000] {dagbag.py:350} ERROR - Failed to import: /opt/airflow/dags/download_NASA_API_dags.py
Traceback (most recent call last):
  File "/home/airflow/.local/lib/python3.8/site-packages/airflow/models/dagbag.py", line 346, in parse
    loader.exec_module(new_module)
  File "<frozen importlib._bootstrap_external>", line 843, in exec_module
  File "<frozen importlib._bootstrap>", line 219, in _call_with_frames_removed
  File "/opt/airflow/dags/download_NASA_API_dags.py", line 15, in <module>
    os.makedirs(output_estado_raw, exist_ok=True)
  File "/usr/local/lib/python3.8/os.py", line 213, in makedirs
    makedirs(head, exist_ok=exist_ok)
  File "/usr/local/lib/python3.8/os.py", line 213, in makedirs
    makedirs(head, exist_ok=exist_ok)
  File "/usr/local/lib/python3.8/os.py", line 223, in makedirs
    mkdir(name, mode)
PermissionError: [Errno 13] Permission denied: '/usr/local/airflow'
[2024-04-02T01:03:34.427+0000] {processor.py:842} WARNING - No viable dags retrieved from /opt/airflow/dags/download_NASA_API_dags.py
[2024-04-02T01:03:34.500+0000] {processor.py:183} INFO - Processing /opt/airflow/dags/download_NASA_API_dags.py took 0.804 seconds
[2024-04-02T01:06:03.967+0000] {processor.py:161} INFO - Started process (PID=72) to work on /opt/airflow/dags/download_NASA_API_dags.py
[2024-04-02T01:06:03.968+0000] {processor.py:830} INFO - Processing file /opt/airflow/dags/download_NASA_API_dags.py for tasks to queue
[2024-04-02T01:06:03.969+0000] {logging_mixin.py:188} INFO - [2024-04-02T01:06:03.968+0000] {dagbag.py:540} INFO - Filling up the DagBag from /opt/airflow/dags/download_NASA_API_dags.py
[2024-04-02T01:06:19.550+0000] {logging_mixin.py:188} INFO - [2024-04-02T01:06:19.545+0000] {dagbag.py:350} ERROR - Failed to import: /opt/airflow/dags/download_NASA_API_dags.py
Traceback (most recent call last):
  File "/home/airflow/.local/lib/python3.8/site-packages/airflow/models/dagbag.py", line 346, in parse
    loader.exec_module(new_module)
  File "<frozen importlib._bootstrap_external>", line 843, in exec_module
  File "<frozen importlib._bootstrap>", line 219, in _call_with_frames_removed
  File "/opt/airflow/dags/download_NASA_API_dags.py", line 15, in <module>
    os.makedirs(output_estado_raw, exist_ok=True)
  File "/usr/local/lib/python3.8/os.py", line 213, in makedirs
    makedirs(head, exist_ok=exist_ok)
  File "/usr/local/lib/python3.8/os.py", line 213, in makedirs
    makedirs(head, exist_ok=exist_ok)
  File "/usr/local/lib/python3.8/os.py", line 223, in makedirs
    mkdir(name, mode)
PermissionError: [Errno 13] Permission denied: '/usr/local/airflow'
[2024-04-02T01:06:19.551+0000] {processor.py:842} WARNING - No viable dags retrieved from /opt/airflow/dags/download_NASA_API_dags.py
[2024-04-02T01:06:19.586+0000] {processor.py:183} INFO - Processing /opt/airflow/dags/download_NASA_API_dags.py took 15.622 seconds
[2024-04-02T01:06:49.991+0000] {processor.py:161} INFO - Started process (PID=97) to work on /opt/airflow/dags/download_NASA_API_dags.py
[2024-04-02T01:06:49.992+0000] {processor.py:830} INFO - Processing file /opt/airflow/dags/download_NASA_API_dags.py for tasks to queue
[2024-04-02T01:06:49.994+0000] {logging_mixin.py:188} INFO - [2024-04-02T01:06:49.993+0000] {dagbag.py:540} INFO - Filling up the DagBag from /opt/airflow/dags/download_NASA_API_dags.py
[2024-04-02T01:06:50.657+0000] {logging_mixin.py:188} INFO - [2024-04-02T01:06:50.648+0000] {dagbag.py:350} ERROR - Failed to import: /opt/airflow/dags/download_NASA_API_dags.py
Traceback (most recent call last):
  File "/home/airflow/.local/lib/python3.8/site-packages/airflow/models/dagbag.py", line 346, in parse
    loader.exec_module(new_module)
  File "<frozen importlib._bootstrap_external>", line 843, in exec_module
  File "<frozen importlib._bootstrap>", line 219, in _call_with_frames_removed
  File "/opt/airflow/dags/download_NASA_API_dags.py", line 15, in <module>
    os.makedirs(output_estado_raw, exist_ok=True)
  File "/usr/local/lib/python3.8/os.py", line 213, in makedirs
    makedirs(head, exist_ok=exist_ok)
  File "/usr/local/lib/python3.8/os.py", line 213, in makedirs
    makedirs(head, exist_ok=exist_ok)
  File "/usr/local/lib/python3.8/os.py", line 223, in makedirs
    mkdir(name, mode)
PermissionError: [Errno 13] Permission denied: '/usr/local/airflow'
[2024-04-02T01:06:50.658+0000] {processor.py:842} WARNING - No viable dags retrieved from /opt/airflow/dags/download_NASA_API_dags.py
[2024-04-02T01:06:50.708+0000] {processor.py:183} INFO - Processing /opt/airflow/dags/download_NASA_API_dags.py took 0.721 seconds
[2024-04-02T01:07:21.178+0000] {processor.py:161} INFO - Started process (PID=100) to work on /opt/airflow/dags/download_NASA_API_dags.py
[2024-04-02T01:07:21.180+0000] {processor.py:830} INFO - Processing file /opt/airflow/dags/download_NASA_API_dags.py for tasks to queue
[2024-04-02T01:07:21.182+0000] {logging_mixin.py:188} INFO - [2024-04-02T01:07:21.181+0000] {dagbag.py:540} INFO - Filling up the DagBag from /opt/airflow/dags/download_NASA_API_dags.py
[2024-04-02T01:07:21.810+0000] {logging_mixin.py:188} INFO - [2024-04-02T01:07:21.803+0000] {dagbag.py:350} ERROR - Failed to import: /opt/airflow/dags/download_NASA_API_dags.py
Traceback (most recent call last):
  File "/home/airflow/.local/lib/python3.8/site-packages/airflow/models/dagbag.py", line 346, in parse
    loader.exec_module(new_module)
  File "<frozen importlib._bootstrap_external>", line 843, in exec_module
  File "<frozen importlib._bootstrap>", line 219, in _call_with_frames_removed
  File "/opt/airflow/dags/download_NASA_API_dags.py", line 15, in <module>
    os.makedirs(output_estado_raw, exist_ok=True)
  File "/usr/local/lib/python3.8/os.py", line 213, in makedirs
    makedirs(head, exist_ok=exist_ok)
  File "/usr/local/lib/python3.8/os.py", line 213, in makedirs
    makedirs(head, exist_ok=exist_ok)
  File "/usr/local/lib/python3.8/os.py", line 223, in makedirs
    mkdir(name, mode)
PermissionError: [Errno 13] Permission denied: '/usr/local/airflow'
[2024-04-02T01:07:21.811+0000] {processor.py:842} WARNING - No viable dags retrieved from /opt/airflow/dags/download_NASA_API_dags.py
[2024-04-02T01:07:21.870+0000] {processor.py:183} INFO - Processing /opt/airflow/dags/download_NASA_API_dags.py took 0.694 seconds
[2024-04-02T01:07:52.306+0000] {processor.py:161} INFO - Started process (PID=103) to work on /opt/airflow/dags/download_NASA_API_dags.py
[2024-04-02T01:07:52.307+0000] {processor.py:830} INFO - Processing file /opt/airflow/dags/download_NASA_API_dags.py for tasks to queue
[2024-04-02T01:07:52.308+0000] {logging_mixin.py:188} INFO - [2024-04-02T01:07:52.308+0000] {dagbag.py:540} INFO - Filling up the DagBag from /opt/airflow/dags/download_NASA_API_dags.py
[2024-04-02T01:07:52.838+0000] {logging_mixin.py:188} INFO - [2024-04-02T01:07:52.832+0000] {dagbag.py:350} ERROR - Failed to import: /opt/airflow/dags/download_NASA_API_dags.py
Traceback (most recent call last):
  File "/home/airflow/.local/lib/python3.8/site-packages/airflow/models/dagbag.py", line 346, in parse
    loader.exec_module(new_module)
  File "<frozen importlib._bootstrap_external>", line 843, in exec_module
  File "<frozen importlib._bootstrap>", line 219, in _call_with_frames_removed
  File "/opt/airflow/dags/download_NASA_API_dags.py", line 15, in <module>
    os.makedirs(output_estado_raw, exist_ok=True)
  File "/usr/local/lib/python3.8/os.py", line 213, in makedirs
    makedirs(head, exist_ok=exist_ok)
  File "/usr/local/lib/python3.8/os.py", line 213, in makedirs
    makedirs(head, exist_ok=exist_ok)
  File "/usr/local/lib/python3.8/os.py", line 223, in makedirs
    mkdir(name, mode)
PermissionError: [Errno 13] Permission denied: '/usr/local/airflow'
[2024-04-02T01:07:52.839+0000] {processor.py:842} WARNING - No viable dags retrieved from /opt/airflow/dags/download_NASA_API_dags.py
[2024-04-02T01:07:52.890+0000] {processor.py:183} INFO - Processing /opt/airflow/dags/download_NASA_API_dags.py took 0.587 seconds
[2024-04-02T01:08:23.227+0000] {processor.py:161} INFO - Started process (PID=106) to work on /opt/airflow/dags/download_NASA_API_dags.py
[2024-04-02T01:08:23.229+0000] {processor.py:830} INFO - Processing file /opt/airflow/dags/download_NASA_API_dags.py for tasks to queue
[2024-04-02T01:08:23.231+0000] {logging_mixin.py:188} INFO - [2024-04-02T01:08:23.230+0000] {dagbag.py:540} INFO - Filling up the DagBag from /opt/airflow/dags/download_NASA_API_dags.py
[2024-04-02T01:08:24.134+0000] {logging_mixin.py:188} INFO - [2024-04-02T01:08:24.126+0000] {dagbag.py:350} ERROR - Failed to import: /opt/airflow/dags/download_NASA_API_dags.py
Traceback (most recent call last):
  File "/home/airflow/.local/lib/python3.8/site-packages/airflow/models/dagbag.py", line 346, in parse
    loader.exec_module(new_module)
  File "<frozen importlib._bootstrap_external>", line 843, in exec_module
  File "<frozen importlib._bootstrap>", line 219, in _call_with_frames_removed
  File "/opt/airflow/dags/download_NASA_API_dags.py", line 15, in <module>
    os.makedirs(output_estado_raw, exist_ok=True)
  File "/usr/local/lib/python3.8/os.py", line 213, in makedirs
    makedirs(head, exist_ok=exist_ok)
  File "/usr/local/lib/python3.8/os.py", line 213, in makedirs
    makedirs(head, exist_ok=exist_ok)
  File "/usr/local/lib/python3.8/os.py", line 223, in makedirs
    mkdir(name, mode)
PermissionError: [Errno 13] Permission denied: '/usr/local/airflow'
[2024-04-02T01:08:24.135+0000] {processor.py:842} WARNING - No viable dags retrieved from /opt/airflow/dags/download_NASA_API_dags.py
[2024-04-02T01:08:24.193+0000] {processor.py:183} INFO - Processing /opt/airflow/dags/download_NASA_API_dags.py took 0.970 seconds
[2024-04-02T01:08:54.612+0000] {processor.py:161} INFO - Started process (PID=110) to work on /opt/airflow/dags/download_NASA_API_dags.py
[2024-04-02T01:08:54.614+0000] {processor.py:830} INFO - Processing file /opt/airflow/dags/download_NASA_API_dags.py for tasks to queue
[2024-04-02T01:08:54.615+0000] {logging_mixin.py:188} INFO - [2024-04-02T01:08:54.615+0000] {dagbag.py:540} INFO - Filling up the DagBag from /opt/airflow/dags/download_NASA_API_dags.py
[2024-04-02T01:08:55.324+0000] {logging_mixin.py:188} INFO - [2024-04-02T01:08:55.314+0000] {dagbag.py:350} ERROR - Failed to import: /opt/airflow/dags/download_NASA_API_dags.py
Traceback (most recent call last):
  File "/home/airflow/.local/lib/python3.8/site-packages/airflow/models/dagbag.py", line 346, in parse
    loader.exec_module(new_module)
  File "<frozen importlib._bootstrap_external>", line 843, in exec_module
  File "<frozen importlib._bootstrap>", line 219, in _call_with_frames_removed
  File "/opt/airflow/dags/download_NASA_API_dags.py", line 15, in <module>
    os.makedirs(output_estado_raw, exist_ok=True)
  File "/usr/local/lib/python3.8/os.py", line 213, in makedirs
    makedirs(head, exist_ok=exist_ok)
  File "/usr/local/lib/python3.8/os.py", line 213, in makedirs
    makedirs(head, exist_ok=exist_ok)
  File "/usr/local/lib/python3.8/os.py", line 223, in makedirs
    mkdir(name, mode)
PermissionError: [Errno 13] Permission denied: '/usr/local/airflow'
[2024-04-02T01:08:55.325+0000] {processor.py:842} WARNING - No viable dags retrieved from /opt/airflow/dags/download_NASA_API_dags.py
[2024-04-02T01:08:55.380+0000] {processor.py:183} INFO - Processing /opt/airflow/dags/download_NASA_API_dags.py took 0.772 seconds
[2024-04-02T01:09:25.755+0000] {processor.py:161} INFO - Started process (PID=113) to work on /opt/airflow/dags/download_NASA_API_dags.py
[2024-04-02T01:09:25.757+0000] {processor.py:830} INFO - Processing file /opt/airflow/dags/download_NASA_API_dags.py for tasks to queue
[2024-04-02T01:09:25.758+0000] {logging_mixin.py:188} INFO - [2024-04-02T01:09:25.758+0000] {dagbag.py:540} INFO - Filling up the DagBag from /opt/airflow/dags/download_NASA_API_dags.py
[2024-04-02T01:09:26.425+0000] {logging_mixin.py:188} INFO - [2024-04-02T01:09:26.417+0000] {dagbag.py:350} ERROR - Failed to import: /opt/airflow/dags/download_NASA_API_dags.py
Traceback (most recent call last):
  File "/home/airflow/.local/lib/python3.8/site-packages/airflow/models/dagbag.py", line 346, in parse
    loader.exec_module(new_module)
  File "<frozen importlib._bootstrap_external>", line 843, in exec_module
  File "<frozen importlib._bootstrap>", line 219, in _call_with_frames_removed
  File "/opt/airflow/dags/download_NASA_API_dags.py", line 15, in <module>
    os.makedirs(output_estado_raw, exist_ok=True)
  File "/usr/local/lib/python3.8/os.py", line 213, in makedirs
    makedirs(head, exist_ok=exist_ok)
  File "/usr/local/lib/python3.8/os.py", line 213, in makedirs
    makedirs(head, exist_ok=exist_ok)
  File "/usr/local/lib/python3.8/os.py", line 223, in makedirs
    mkdir(name, mode)
PermissionError: [Errno 13] Permission denied: '/usr/local/airflow'
[2024-04-02T01:09:26.427+0000] {processor.py:842} WARNING - No viable dags retrieved from /opt/airflow/dags/download_NASA_API_dags.py
[2024-04-02T01:09:26.494+0000] {processor.py:183} INFO - Processing /opt/airflow/dags/download_NASA_API_dags.py took 0.743 seconds
[2024-04-02T01:09:56.923+0000] {processor.py:161} INFO - Started process (PID=116) to work on /opt/airflow/dags/download_NASA_API_dags.py
[2024-04-02T01:09:56.925+0000] {processor.py:830} INFO - Processing file /opt/airflow/dags/download_NASA_API_dags.py for tasks to queue
[2024-04-02T01:09:56.926+0000] {logging_mixin.py:188} INFO - [2024-04-02T01:09:56.926+0000] {dagbag.py:540} INFO - Filling up the DagBag from /opt/airflow/dags/download_NASA_API_dags.py
[2024-04-02T01:09:57.606+0000] {logging_mixin.py:188} INFO - [2024-04-02T01:09:57.598+0000] {dagbag.py:350} ERROR - Failed to import: /opt/airflow/dags/download_NASA_API_dags.py
Traceback (most recent call last):
  File "/home/airflow/.local/lib/python3.8/site-packages/airflow/models/dagbag.py", line 346, in parse
    loader.exec_module(new_module)
  File "<frozen importlib._bootstrap_external>", line 843, in exec_module
  File "<frozen importlib._bootstrap>", line 219, in _call_with_frames_removed
  File "/opt/airflow/dags/download_NASA_API_dags.py", line 15, in <module>
    os.makedirs(output_estado_raw, exist_ok=True)
  File "/usr/local/lib/python3.8/os.py", line 213, in makedirs
    makedirs(head, exist_ok=exist_ok)
  File "/usr/local/lib/python3.8/os.py", line 213, in makedirs
    makedirs(head, exist_ok=exist_ok)
  File "/usr/local/lib/python3.8/os.py", line 223, in makedirs
    mkdir(name, mode)
PermissionError: [Errno 13] Permission denied: '/usr/local/airflow'
[2024-04-02T01:09:57.608+0000] {processor.py:842} WARNING - No viable dags retrieved from /opt/airflow/dags/download_NASA_API_dags.py
[2024-04-02T01:09:57.674+0000] {processor.py:183} INFO - Processing /opt/airflow/dags/download_NASA_API_dags.py took 0.754 seconds
[2024-04-02T01:10:28.003+0000] {processor.py:161} INFO - Started process (PID=119) to work on /opt/airflow/dags/download_NASA_API_dags.py
[2024-04-02T01:10:28.005+0000] {processor.py:830} INFO - Processing file /opt/airflow/dags/download_NASA_API_dags.py for tasks to queue
[2024-04-02T01:10:28.006+0000] {logging_mixin.py:188} INFO - [2024-04-02T01:10:28.006+0000] {dagbag.py:540} INFO - Filling up the DagBag from /opt/airflow/dags/download_NASA_API_dags.py
[2024-04-02T01:10:28.680+0000] {logging_mixin.py:188} INFO - [2024-04-02T01:10:28.672+0000] {dagbag.py:350} ERROR - Failed to import: /opt/airflow/dags/download_NASA_API_dags.py
Traceback (most recent call last):
  File "/home/airflow/.local/lib/python3.8/site-packages/airflow/models/dagbag.py", line 346, in parse
    loader.exec_module(new_module)
  File "<frozen importlib._bootstrap_external>", line 843, in exec_module
  File "<frozen importlib._bootstrap>", line 219, in _call_with_frames_removed
  File "/opt/airflow/dags/download_NASA_API_dags.py", line 15, in <module>
    os.makedirs(output_estado_raw, exist_ok=True)
  File "/usr/local/lib/python3.8/os.py", line 213, in makedirs
    makedirs(head, exist_ok=exist_ok)
  File "/usr/local/lib/python3.8/os.py", line 213, in makedirs
    makedirs(head, exist_ok=exist_ok)
  File "/usr/local/lib/python3.8/os.py", line 223, in makedirs
    mkdir(name, mode)
PermissionError: [Errno 13] Permission denied: '/usr/local/airflow'
[2024-04-02T01:10:28.681+0000] {processor.py:842} WARNING - No viable dags retrieved from /opt/airflow/dags/download_NASA_API_dags.py
[2024-04-02T01:10:28.743+0000] {processor.py:183} INFO - Processing /opt/airflow/dags/download_NASA_API_dags.py took 0.743 seconds
[2024-04-02T01:10:59.193+0000] {processor.py:161} INFO - Started process (PID=122) to work on /opt/airflow/dags/download_NASA_API_dags.py
[2024-04-02T01:10:59.195+0000] {processor.py:830} INFO - Processing file /opt/airflow/dags/download_NASA_API_dags.py for tasks to queue
[2024-04-02T01:10:59.197+0000] {logging_mixin.py:188} INFO - [2024-04-02T01:10:59.196+0000] {dagbag.py:540} INFO - Filling up the DagBag from /opt/airflow/dags/download_NASA_API_dags.py
[2024-04-02T01:10:59.903+0000] {logging_mixin.py:188} INFO - [2024-04-02T01:10:59.894+0000] {dagbag.py:350} ERROR - Failed to import: /opt/airflow/dags/download_NASA_API_dags.py
Traceback (most recent call last):
  File "/home/airflow/.local/lib/python3.8/site-packages/airflow/models/dagbag.py", line 346, in parse
    loader.exec_module(new_module)
  File "<frozen importlib._bootstrap_external>", line 843, in exec_module
  File "<frozen importlib._bootstrap>", line 219, in _call_with_frames_removed
  File "/opt/airflow/dags/download_NASA_API_dags.py", line 15, in <module>
    os.makedirs(output_estado_raw, exist_ok=True)
  File "/usr/local/lib/python3.8/os.py", line 213, in makedirs
    makedirs(head, exist_ok=exist_ok)
  File "/usr/local/lib/python3.8/os.py", line 213, in makedirs
    makedirs(head, exist_ok=exist_ok)
  File "/usr/local/lib/python3.8/os.py", line 223, in makedirs
    mkdir(name, mode)
PermissionError: [Errno 13] Permission denied: '/usr/local/airflow'
[2024-04-02T01:10:59.904+0000] {processor.py:842} WARNING - No viable dags retrieved from /opt/airflow/dags/download_NASA_API_dags.py
[2024-04-02T01:10:59.977+0000] {processor.py:183} INFO - Processing /opt/airflow/dags/download_NASA_API_dags.py took 0.790 seconds
[2024-04-02T01:11:30.522+0000] {processor.py:161} INFO - Started process (PID=125) to work on /opt/airflow/dags/download_NASA_API_dags.py
[2024-04-02T01:11:30.524+0000] {processor.py:830} INFO - Processing file /opt/airflow/dags/download_NASA_API_dags.py for tasks to queue
[2024-04-02T01:11:30.526+0000] {logging_mixin.py:188} INFO - [2024-04-02T01:11:30.525+0000] {dagbag.py:540} INFO - Filling up the DagBag from /opt/airflow/dags/download_NASA_API_dags.py
[2024-04-02T01:11:31.258+0000] {logging_mixin.py:188} INFO - [2024-04-02T01:11:31.250+0000] {dagbag.py:350} ERROR - Failed to import: /opt/airflow/dags/download_NASA_API_dags.py
Traceback (most recent call last):
  File "/home/airflow/.local/lib/python3.8/site-packages/airflow/models/dagbag.py", line 346, in parse
    loader.exec_module(new_module)
  File "<frozen importlib._bootstrap_external>", line 843, in exec_module
  File "<frozen importlib._bootstrap>", line 219, in _call_with_frames_removed
  File "/opt/airflow/dags/download_NASA_API_dags.py", line 15, in <module>
    os.makedirs(output_estado_raw, exist_ok=True)
  File "/usr/local/lib/python3.8/os.py", line 213, in makedirs
    makedirs(head, exist_ok=exist_ok)
  File "/usr/local/lib/python3.8/os.py", line 213, in makedirs
    makedirs(head, exist_ok=exist_ok)
  File "/usr/local/lib/python3.8/os.py", line 223, in makedirs
    mkdir(name, mode)
PermissionError: [Errno 13] Permission denied: '/usr/local/airflow'
[2024-04-02T01:11:31.259+0000] {processor.py:842} WARNING - No viable dags retrieved from /opt/airflow/dags/download_NASA_API_dags.py
[2024-04-02T01:11:31.321+0000] {processor.py:183} INFO - Processing /opt/airflow/dags/download_NASA_API_dags.py took 0.802 seconds
[2024-04-02T01:12:01.766+0000] {processor.py:161} INFO - Started process (PID=128) to work on /opt/airflow/dags/download_NASA_API_dags.py
[2024-04-02T01:12:01.768+0000] {processor.py:830} INFO - Processing file /opt/airflow/dags/download_NASA_API_dags.py for tasks to queue
[2024-04-02T01:12:01.769+0000] {logging_mixin.py:188} INFO - [2024-04-02T01:12:01.769+0000] {dagbag.py:540} INFO - Filling up the DagBag from /opt/airflow/dags/download_NASA_API_dags.py
[2024-04-02T01:12:02.403+0000] {logging_mixin.py:188} INFO - [2024-04-02T01:12:02.395+0000] {dagbag.py:350} ERROR - Failed to import: /opt/airflow/dags/download_NASA_API_dags.py
Traceback (most recent call last):
  File "/home/airflow/.local/lib/python3.8/site-packages/airflow/models/dagbag.py", line 346, in parse
    loader.exec_module(new_module)
  File "<frozen importlib._bootstrap_external>", line 843, in exec_module
  File "<frozen importlib._bootstrap>", line 219, in _call_with_frames_removed
  File "/opt/airflow/dags/download_NASA_API_dags.py", line 15, in <module>
    os.makedirs(output_estado_raw, exist_ok=True)
  File "/usr/local/lib/python3.8/os.py", line 213, in makedirs
    makedirs(head, exist_ok=exist_ok)
  File "/usr/local/lib/python3.8/os.py", line 213, in makedirs
    makedirs(head, exist_ok=exist_ok)
  File "/usr/local/lib/python3.8/os.py", line 223, in makedirs
    mkdir(name, mode)
PermissionError: [Errno 13] Permission denied: '/usr/local/airflow'
[2024-04-02T01:12:02.404+0000] {processor.py:842} WARNING - No viable dags retrieved from /opt/airflow/dags/download_NASA_API_dags.py
[2024-04-02T01:12:02.472+0000] {processor.py:183} INFO - Processing /opt/airflow/dags/download_NASA_API_dags.py took 0.710 seconds
[2024-04-02T01:12:32.901+0000] {processor.py:161} INFO - Started process (PID=131) to work on /opt/airflow/dags/download_NASA_API_dags.py
[2024-04-02T01:12:32.903+0000] {processor.py:830} INFO - Processing file /opt/airflow/dags/download_NASA_API_dags.py for tasks to queue
[2024-04-02T01:12:32.904+0000] {logging_mixin.py:188} INFO - [2024-04-02T01:12:32.904+0000] {dagbag.py:540} INFO - Filling up the DagBag from /opt/airflow/dags/download_NASA_API_dags.py
[2024-04-02T01:12:33.539+0000] {logging_mixin.py:188} INFO - [2024-04-02T01:12:33.532+0000] {dagbag.py:350} ERROR - Failed to import: /opt/airflow/dags/download_NASA_API_dags.py
Traceback (most recent call last):
  File "/home/airflow/.local/lib/python3.8/site-packages/airflow/models/dagbag.py", line 346, in parse
    loader.exec_module(new_module)
  File "<frozen importlib._bootstrap_external>", line 843, in exec_module
  File "<frozen importlib._bootstrap>", line 219, in _call_with_frames_removed
  File "/opt/airflow/dags/download_NASA_API_dags.py", line 15, in <module>
    os.makedirs(output_estado_raw, exist_ok=True)
  File "/usr/local/lib/python3.8/os.py", line 213, in makedirs
    makedirs(head, exist_ok=exist_ok)
  File "/usr/local/lib/python3.8/os.py", line 213, in makedirs
    makedirs(head, exist_ok=exist_ok)
  File "/usr/local/lib/python3.8/os.py", line 223, in makedirs
    mkdir(name, mode)
PermissionError: [Errno 13] Permission denied: '/usr/local/airflow'
[2024-04-02T01:12:33.540+0000] {processor.py:842} WARNING - No viable dags retrieved from /opt/airflow/dags/download_NASA_API_dags.py
[2024-04-02T01:12:33.598+0000] {processor.py:183} INFO - Processing /opt/airflow/dags/download_NASA_API_dags.py took 0.700 seconds
[2024-04-02T01:13:04.015+0000] {processor.py:161} INFO - Started process (PID=134) to work on /opt/airflow/dags/download_NASA_API_dags.py
[2024-04-02T01:13:04.016+0000] {processor.py:830} INFO - Processing file /opt/airflow/dags/download_NASA_API_dags.py for tasks to queue
[2024-04-02T01:13:04.018+0000] {logging_mixin.py:188} INFO - [2024-04-02T01:13:04.017+0000] {dagbag.py:540} INFO - Filling up the DagBag from /opt/airflow/dags/download_NASA_API_dags.py
[2024-04-02T01:13:04.660+0000] {logging_mixin.py:188} INFO - [2024-04-02T01:13:04.652+0000] {dagbag.py:350} ERROR - Failed to import: /opt/airflow/dags/download_NASA_API_dags.py
Traceback (most recent call last):
  File "/home/airflow/.local/lib/python3.8/site-packages/airflow/models/dagbag.py", line 346, in parse
    loader.exec_module(new_module)
  File "<frozen importlib._bootstrap_external>", line 843, in exec_module
  File "<frozen importlib._bootstrap>", line 219, in _call_with_frames_removed
  File "/opt/airflow/dags/download_NASA_API_dags.py", line 15, in <module>
    os.makedirs(output_estado_raw, exist_ok=True)
  File "/usr/local/lib/python3.8/os.py", line 213, in makedirs
    makedirs(head, exist_ok=exist_ok)
  File "/usr/local/lib/python3.8/os.py", line 213, in makedirs
    makedirs(head, exist_ok=exist_ok)
  File "/usr/local/lib/python3.8/os.py", line 223, in makedirs
    mkdir(name, mode)
PermissionError: [Errno 13] Permission denied: '/usr/local/airflow'
[2024-04-02T01:13:04.661+0000] {processor.py:842} WARNING - No viable dags retrieved from /opt/airflow/dags/download_NASA_API_dags.py
[2024-04-02T01:13:04.723+0000] {processor.py:183} INFO - Processing /opt/airflow/dags/download_NASA_API_dags.py took 0.712 seconds
[2024-04-02T01:13:35.139+0000] {processor.py:161} INFO - Started process (PID=137) to work on /opt/airflow/dags/download_NASA_API_dags.py
[2024-04-02T01:13:35.141+0000] {processor.py:830} INFO - Processing file /opt/airflow/dags/download_NASA_API_dags.py for tasks to queue
[2024-04-02T01:13:35.143+0000] {logging_mixin.py:188} INFO - [2024-04-02T01:13:35.142+0000] {dagbag.py:540} INFO - Filling up the DagBag from /opt/airflow/dags/download_NASA_API_dags.py
[2024-04-02T01:13:35.923+0000] {logging_mixin.py:188} INFO - [2024-04-02T01:13:35.915+0000] {dagbag.py:350} ERROR - Failed to import: /opt/airflow/dags/download_NASA_API_dags.py
Traceback (most recent call last):
  File "/home/airflow/.local/lib/python3.8/site-packages/airflow/models/dagbag.py", line 346, in parse
    loader.exec_module(new_module)
  File "<frozen importlib._bootstrap_external>", line 843, in exec_module
  File "<frozen importlib._bootstrap>", line 219, in _call_with_frames_removed
  File "/opt/airflow/dags/download_NASA_API_dags.py", line 15, in <module>
    os.makedirs(output_estado_raw, exist_ok=True)
  File "/usr/local/lib/python3.8/os.py", line 213, in makedirs
    makedirs(head, exist_ok=exist_ok)
  File "/usr/local/lib/python3.8/os.py", line 213, in makedirs
    makedirs(head, exist_ok=exist_ok)
  File "/usr/local/lib/python3.8/os.py", line 223, in makedirs
    mkdir(name, mode)
PermissionError: [Errno 13] Permission denied: '/usr/local/airflow'
[2024-04-02T01:13:35.924+0000] {processor.py:842} WARNING - No viable dags retrieved from /opt/airflow/dags/download_NASA_API_dags.py
[2024-04-02T01:13:35.983+0000] {processor.py:183} INFO - Processing /opt/airflow/dags/download_NASA_API_dags.py took 0.849 seconds
[2024-04-02T01:14:06.176+0000] {processor.py:161} INFO - Started process (PID=140) to work on /opt/airflow/dags/download_NASA_API_dags.py
[2024-04-02T01:14:06.177+0000] {processor.py:830} INFO - Processing file /opt/airflow/dags/download_NASA_API_dags.py for tasks to queue
[2024-04-02T01:14:06.179+0000] {logging_mixin.py:188} INFO - [2024-04-02T01:14:06.178+0000] {dagbag.py:540} INFO - Filling up the DagBag from /opt/airflow/dags/download_NASA_API_dags.py
[2024-04-02T01:14:06.763+0000] {logging_mixin.py:188} INFO - [2024-04-02T01:14:06.755+0000] {dagbag.py:350} ERROR - Failed to import: /opt/airflow/dags/download_NASA_API_dags.py
Traceback (most recent call last):
  File "/home/airflow/.local/lib/python3.8/site-packages/airflow/models/dagbag.py", line 346, in parse
    loader.exec_module(new_module)
  File "<frozen importlib._bootstrap_external>", line 843, in exec_module
  File "<frozen importlib._bootstrap>", line 219, in _call_with_frames_removed
  File "/opt/airflow/dags/download_NASA_API_dags.py", line 15, in <module>
    os.makedirs(output_estado_raw, exist_ok=True)
  File "/usr/local/lib/python3.8/os.py", line 213, in makedirs
    makedirs(head, exist_ok=exist_ok)
  File "/usr/local/lib/python3.8/os.py", line 213, in makedirs
    makedirs(head, exist_ok=exist_ok)
  File "/usr/local/lib/python3.8/os.py", line 223, in makedirs
    mkdir(name, mode)
PermissionError: [Errno 13] Permission denied: '/usr/local/airflow'
[2024-04-02T01:14:06.763+0000] {processor.py:842} WARNING - No viable dags retrieved from /opt/airflow/dags/download_NASA_API_dags.py
[2024-04-02T01:14:06.821+0000] {processor.py:183} INFO - Processing /opt/airflow/dags/download_NASA_API_dags.py took 0.648 seconds
[2024-04-02T01:14:37.076+0000] {processor.py:161} INFO - Started process (PID=143) to work on /opt/airflow/dags/download_NASA_API_dags.py
[2024-04-02T01:14:37.077+0000] {processor.py:830} INFO - Processing file /opt/airflow/dags/download_NASA_API_dags.py for tasks to queue
[2024-04-02T01:14:37.078+0000] {logging_mixin.py:188} INFO - [2024-04-02T01:14:37.078+0000] {dagbag.py:540} INFO - Filling up the DagBag from /opt/airflow/dags/download_NASA_API_dags.py
[2024-04-02T01:14:38.275+0000] {logging_mixin.py:188} INFO - [2024-04-02T01:14:38.267+0000] {dagbag.py:350} ERROR - Failed to import: /opt/airflow/dags/download_NASA_API_dags.py
Traceback (most recent call last):
  File "/home/airflow/.local/lib/python3.8/site-packages/airflow/models/dagbag.py", line 346, in parse
    loader.exec_module(new_module)
  File "<frozen importlib._bootstrap_external>", line 843, in exec_module
  File "<frozen importlib._bootstrap>", line 219, in _call_with_frames_removed
  File "/opt/airflow/dags/download_NASA_API_dags.py", line 15, in <module>
    os.makedirs(output_estado_raw, exist_ok=True)
  File "/usr/local/lib/python3.8/os.py", line 213, in makedirs
    makedirs(head, exist_ok=exist_ok)
  File "/usr/local/lib/python3.8/os.py", line 213, in makedirs
    makedirs(head, exist_ok=exist_ok)
  File "/usr/local/lib/python3.8/os.py", line 223, in makedirs
    mkdir(name, mode)
PermissionError: [Errno 13] Permission denied: '/usr/local/airflow'
[2024-04-02T01:14:38.276+0000] {processor.py:842} WARNING - No viable dags retrieved from /opt/airflow/dags/download_NASA_API_dags.py
[2024-04-02T01:14:38.334+0000] {processor.py:183} INFO - Processing /opt/airflow/dags/download_NASA_API_dags.py took 1.262 seconds
[2024-04-02T01:15:08.615+0000] {processor.py:161} INFO - Started process (PID=146) to work on /opt/airflow/dags/download_NASA_API_dags.py
[2024-04-02T01:15:08.617+0000] {processor.py:830} INFO - Processing file /opt/airflow/dags/download_NASA_API_dags.py for tasks to queue
[2024-04-02T01:15:08.618+0000] {logging_mixin.py:188} INFO - [2024-04-02T01:15:08.618+0000] {dagbag.py:540} INFO - Filling up the DagBag from /opt/airflow/dags/download_NASA_API_dags.py
[2024-04-02T01:15:09.282+0000] {logging_mixin.py:188} INFO - [2024-04-02T01:15:09.274+0000] {dagbag.py:350} ERROR - Failed to import: /opt/airflow/dags/download_NASA_API_dags.py
Traceback (most recent call last):
  File "/home/airflow/.local/lib/python3.8/site-packages/airflow/models/dagbag.py", line 346, in parse
    loader.exec_module(new_module)
  File "<frozen importlib._bootstrap_external>", line 843, in exec_module
  File "<frozen importlib._bootstrap>", line 219, in _call_with_frames_removed
  File "/opt/airflow/dags/download_NASA_API_dags.py", line 15, in <module>
    os.makedirs(output_estado_raw, exist_ok=True)
  File "/usr/local/lib/python3.8/os.py", line 213, in makedirs
    makedirs(head, exist_ok=exist_ok)
  File "/usr/local/lib/python3.8/os.py", line 213, in makedirs
    makedirs(head, exist_ok=exist_ok)
  File "/usr/local/lib/python3.8/os.py", line 223, in makedirs
    mkdir(name, mode)
PermissionError: [Errno 13] Permission denied: '/usr/local/airflow'
[2024-04-02T01:15:09.283+0000] {processor.py:842} WARNING - No viable dags retrieved from /opt/airflow/dags/download_NASA_API_dags.py
[2024-04-02T01:15:09.345+0000] {processor.py:183} INFO - Processing /opt/airflow/dags/download_NASA_API_dags.py took 0.733 seconds
[2024-04-02T01:15:39.554+0000] {processor.py:161} INFO - Started process (PID=149) to work on /opt/airflow/dags/download_NASA_API_dags.py
[2024-04-02T01:15:39.555+0000] {processor.py:830} INFO - Processing file /opt/airflow/dags/download_NASA_API_dags.py for tasks to queue
[2024-04-02T01:15:39.557+0000] {logging_mixin.py:188} INFO - [2024-04-02T01:15:39.556+0000] {dagbag.py:540} INFO - Filling up the DagBag from /opt/airflow/dags/download_NASA_API_dags.py
[2024-04-02T01:15:40.203+0000] {logging_mixin.py:188} INFO - [2024-04-02T01:15:40.195+0000] {dagbag.py:350} ERROR - Failed to import: /opt/airflow/dags/download_NASA_API_dags.py
Traceback (most recent call last):
  File "/home/airflow/.local/lib/python3.8/site-packages/airflow/models/dagbag.py", line 346, in parse
    loader.exec_module(new_module)
  File "<frozen importlib._bootstrap_external>", line 843, in exec_module
  File "<frozen importlib._bootstrap>", line 219, in _call_with_frames_removed
  File "/opt/airflow/dags/download_NASA_API_dags.py", line 15, in <module>
    os.makedirs(output_estado_raw, exist_ok=True)
  File "/usr/local/lib/python3.8/os.py", line 213, in makedirs
    makedirs(head, exist_ok=exist_ok)
  File "/usr/local/lib/python3.8/os.py", line 213, in makedirs
    makedirs(head, exist_ok=exist_ok)
  File "/usr/local/lib/python3.8/os.py", line 223, in makedirs
    mkdir(name, mode)
PermissionError: [Errno 13] Permission denied: '/usr/local/airflow'
[2024-04-02T01:15:40.204+0000] {processor.py:842} WARNING - No viable dags retrieved from /opt/airflow/dags/download_NASA_API_dags.py
[2024-04-02T01:15:40.263+0000] {processor.py:183} INFO - Processing /opt/airflow/dags/download_NASA_API_dags.py took 0.713 seconds
[2024-04-02T01:16:10.463+0000] {processor.py:161} INFO - Started process (PID=152) to work on /opt/airflow/dags/download_NASA_API_dags.py
[2024-04-02T01:16:10.464+0000] {processor.py:830} INFO - Processing file /opt/airflow/dags/download_NASA_API_dags.py for tasks to queue
[2024-04-02T01:16:10.466+0000] {logging_mixin.py:188} INFO - [2024-04-02T01:16:10.465+0000] {dagbag.py:540} INFO - Filling up the DagBag from /opt/airflow/dags/download_NASA_API_dags.py
[2024-04-02T01:16:11.163+0000] {logging_mixin.py:188} INFO - [2024-04-02T01:16:11.156+0000] {dagbag.py:350} ERROR - Failed to import: /opt/airflow/dags/download_NASA_API_dags.py
Traceback (most recent call last):
  File "/home/airflow/.local/lib/python3.8/site-packages/airflow/models/dagbag.py", line 346, in parse
    loader.exec_module(new_module)
  File "<frozen importlib._bootstrap_external>", line 843, in exec_module
  File "<frozen importlib._bootstrap>", line 219, in _call_with_frames_removed
  File "/opt/airflow/dags/download_NASA_API_dags.py", line 15, in <module>
    os.makedirs(output_estado_raw, exist_ok=True)
  File "/usr/local/lib/python3.8/os.py", line 213, in makedirs
    makedirs(head, exist_ok=exist_ok)
  File "/usr/local/lib/python3.8/os.py", line 213, in makedirs
    makedirs(head, exist_ok=exist_ok)
  File "/usr/local/lib/python3.8/os.py", line 223, in makedirs
    mkdir(name, mode)
PermissionError: [Errno 13] Permission denied: '/usr/local/airflow'
[2024-04-02T01:16:11.164+0000] {processor.py:842} WARNING - No viable dags retrieved from /opt/airflow/dags/download_NASA_API_dags.py
[2024-04-02T01:16:11.223+0000] {processor.py:183} INFO - Processing /opt/airflow/dags/download_NASA_API_dags.py took 0.763 seconds
[2024-04-02T01:16:41.575+0000] {processor.py:161} INFO - Started process (PID=155) to work on /opt/airflow/dags/download_NASA_API_dags.py
[2024-04-02T01:16:41.576+0000] {processor.py:830} INFO - Processing file /opt/airflow/dags/download_NASA_API_dags.py for tasks to queue
[2024-04-02T01:16:41.578+0000] {logging_mixin.py:188} INFO - [2024-04-02T01:16:41.577+0000] {dagbag.py:540} INFO - Filling up the DagBag from /opt/airflow/dags/download_NASA_API_dags.py
[2024-04-02T01:16:42.168+0000] {logging_mixin.py:188} INFO - [2024-04-02T01:16:42.160+0000] {dagbag.py:350} ERROR - Failed to import: /opt/airflow/dags/download_NASA_API_dags.py
Traceback (most recent call last):
  File "/home/airflow/.local/lib/python3.8/site-packages/airflow/models/dagbag.py", line 346, in parse
    loader.exec_module(new_module)
  File "<frozen importlib._bootstrap_external>", line 843, in exec_module
  File "<frozen importlib._bootstrap>", line 219, in _call_with_frames_removed
  File "/opt/airflow/dags/download_NASA_API_dags.py", line 15, in <module>
    os.makedirs(output_estado_raw, exist_ok=True)
  File "/usr/local/lib/python3.8/os.py", line 213, in makedirs
    makedirs(head, exist_ok=exist_ok)
  File "/usr/local/lib/python3.8/os.py", line 213, in makedirs
    makedirs(head, exist_ok=exist_ok)
  File "/usr/local/lib/python3.8/os.py", line 223, in makedirs
    mkdir(name, mode)
PermissionError: [Errno 13] Permission denied: '/usr/local/airflow'
[2024-04-02T01:16:42.170+0000] {processor.py:842} WARNING - No viable dags retrieved from /opt/airflow/dags/download_NASA_API_dags.py
[2024-04-02T01:16:42.232+0000] {processor.py:183} INFO - Processing /opt/airflow/dags/download_NASA_API_dags.py took 0.660 seconds
[2024-04-02T01:17:12.590+0000] {processor.py:161} INFO - Started process (PID=158) to work on /opt/airflow/dags/download_NASA_API_dags.py
[2024-04-02T01:17:12.591+0000] {processor.py:830} INFO - Processing file /opt/airflow/dags/download_NASA_API_dags.py for tasks to queue
[2024-04-02T01:17:12.593+0000] {logging_mixin.py:188} INFO - [2024-04-02T01:17:12.592+0000] {dagbag.py:540} INFO - Filling up the DagBag from /opt/airflow/dags/download_NASA_API_dags.py
[2024-04-02T01:17:13.200+0000] {logging_mixin.py:188} INFO - [2024-04-02T01:17:13.193+0000] {dagbag.py:350} ERROR - Failed to import: /opt/airflow/dags/download_NASA_API_dags.py
Traceback (most recent call last):
  File "/home/airflow/.local/lib/python3.8/site-packages/airflow/models/dagbag.py", line 346, in parse
    loader.exec_module(new_module)
  File "<frozen importlib._bootstrap_external>", line 843, in exec_module
  File "<frozen importlib._bootstrap>", line 219, in _call_with_frames_removed
  File "/opt/airflow/dags/download_NASA_API_dags.py", line 15, in <module>
    os.makedirs(output_estado_raw, exist_ok=True)
  File "/usr/local/lib/python3.8/os.py", line 213, in makedirs
    makedirs(head, exist_ok=exist_ok)
  File "/usr/local/lib/python3.8/os.py", line 213, in makedirs
    makedirs(head, exist_ok=exist_ok)
  File "/usr/local/lib/python3.8/os.py", line 223, in makedirs
    mkdir(name, mode)
PermissionError: [Errno 13] Permission denied: '/usr/local/airflow'
[2024-04-02T01:17:13.201+0000] {processor.py:842} WARNING - No viable dags retrieved from /opt/airflow/dags/download_NASA_API_dags.py
[2024-04-02T01:17:13.259+0000] {processor.py:183} INFO - Processing /opt/airflow/dags/download_NASA_API_dags.py took 0.674 seconds
[2024-04-02T01:17:43.598+0000] {processor.py:161} INFO - Started process (PID=161) to work on /opt/airflow/dags/download_NASA_API_dags.py
[2024-04-02T01:17:43.599+0000] {processor.py:830} INFO - Processing file /opt/airflow/dags/download_NASA_API_dags.py for tasks to queue
[2024-04-02T01:17:43.601+0000] {logging_mixin.py:188} INFO - [2024-04-02T01:17:43.600+0000] {dagbag.py:540} INFO - Filling up the DagBag from /opt/airflow/dags/download_NASA_API_dags.py
[2024-04-02T01:17:44.290+0000] {logging_mixin.py:188} INFO - [2024-04-02T01:17:44.283+0000] {dagbag.py:350} ERROR - Failed to import: /opt/airflow/dags/download_NASA_API_dags.py
Traceback (most recent call last):
  File "/home/airflow/.local/lib/python3.8/site-packages/airflow/models/dagbag.py", line 346, in parse
    loader.exec_module(new_module)
  File "<frozen importlib._bootstrap_external>", line 843, in exec_module
  File "<frozen importlib._bootstrap>", line 219, in _call_with_frames_removed
  File "/opt/airflow/dags/download_NASA_API_dags.py", line 15, in <module>
    os.makedirs(output_estado_raw, exist_ok=True)
  File "/usr/local/lib/python3.8/os.py", line 213, in makedirs
    makedirs(head, exist_ok=exist_ok)
  File "/usr/local/lib/python3.8/os.py", line 213, in makedirs
    makedirs(head, exist_ok=exist_ok)
  File "/usr/local/lib/python3.8/os.py", line 223, in makedirs
    mkdir(name, mode)
PermissionError: [Errno 13] Permission denied: '/usr/local/airflow'
[2024-04-02T01:17:44.291+0000] {processor.py:842} WARNING - No viable dags retrieved from /opt/airflow/dags/download_NASA_API_dags.py
[2024-04-02T01:17:44.351+0000] {processor.py:183} INFO - Processing /opt/airflow/dags/download_NASA_API_dags.py took 0.758 seconds
[2024-04-02T01:18:14.728+0000] {processor.py:161} INFO - Started process (PID=164) to work on /opt/airflow/dags/download_NASA_API_dags.py
[2024-04-02T01:18:14.730+0000] {processor.py:830} INFO - Processing file /opt/airflow/dags/download_NASA_API_dags.py for tasks to queue
[2024-04-02T01:18:14.731+0000] {logging_mixin.py:188} INFO - [2024-04-02T01:18:14.731+0000] {dagbag.py:540} INFO - Filling up the DagBag from /opt/airflow/dags/download_NASA_API_dags.py
[2024-04-02T01:18:15.418+0000] {logging_mixin.py:188} INFO - [2024-04-02T01:18:15.410+0000] {dagbag.py:350} ERROR - Failed to import: /opt/airflow/dags/download_NASA_API_dags.py
Traceback (most recent call last):
  File "/home/airflow/.local/lib/python3.8/site-packages/airflow/models/dagbag.py", line 346, in parse
    loader.exec_module(new_module)
  File "<frozen importlib._bootstrap_external>", line 843, in exec_module
  File "<frozen importlib._bootstrap>", line 219, in _call_with_frames_removed
  File "/opt/airflow/dags/download_NASA_API_dags.py", line 15, in <module>
    os.makedirs(output_estado_raw, exist_ok=True)
  File "/usr/local/lib/python3.8/os.py", line 213, in makedirs
    makedirs(head, exist_ok=exist_ok)
  File "/usr/local/lib/python3.8/os.py", line 213, in makedirs
    makedirs(head, exist_ok=exist_ok)
  File "/usr/local/lib/python3.8/os.py", line 223, in makedirs
    mkdir(name, mode)
PermissionError: [Errno 13] Permission denied: '/usr/local/airflow'
[2024-04-02T01:18:15.419+0000] {processor.py:842} WARNING - No viable dags retrieved from /opt/airflow/dags/download_NASA_API_dags.py
[2024-04-02T01:18:15.483+0000] {processor.py:183} INFO - Processing /opt/airflow/dags/download_NASA_API_dags.py took 0.759 seconds
[2024-04-02T01:18:45.847+0000] {processor.py:161} INFO - Started process (PID=167) to work on /opt/airflow/dags/download_NASA_API_dags.py
[2024-04-02T01:18:45.849+0000] {processor.py:830} INFO - Processing file /opt/airflow/dags/download_NASA_API_dags.py for tasks to queue
[2024-04-02T01:18:45.850+0000] {logging_mixin.py:188} INFO - [2024-04-02T01:18:45.850+0000] {dagbag.py:540} INFO - Filling up the DagBag from /opt/airflow/dags/download_NASA_API_dags.py
[2024-04-02T01:18:46.695+0000] {logging_mixin.py:188} INFO - [2024-04-02T01:18:46.687+0000] {dagbag.py:350} ERROR - Failed to import: /opt/airflow/dags/download_NASA_API_dags.py
Traceback (most recent call last):
  File "/home/airflow/.local/lib/python3.8/site-packages/airflow/models/dagbag.py", line 346, in parse
    loader.exec_module(new_module)
  File "<frozen importlib._bootstrap_external>", line 843, in exec_module
  File "<frozen importlib._bootstrap>", line 219, in _call_with_frames_removed
  File "/opt/airflow/dags/download_NASA_API_dags.py", line 15, in <module>
    os.makedirs(output_estado_raw, exist_ok=True)
  File "/usr/local/lib/python3.8/os.py", line 213, in makedirs
    makedirs(head, exist_ok=exist_ok)
  File "/usr/local/lib/python3.8/os.py", line 213, in makedirs
    makedirs(head, exist_ok=exist_ok)
  File "/usr/local/lib/python3.8/os.py", line 223, in makedirs
    mkdir(name, mode)
PermissionError: [Errno 13] Permission denied: '/usr/local/airflow'
[2024-04-02T01:18:46.695+0000] {processor.py:842} WARNING - No viable dags retrieved from /opt/airflow/dags/download_NASA_API_dags.py
[2024-04-02T01:18:46.757+0000] {processor.py:183} INFO - Processing /opt/airflow/dags/download_NASA_API_dags.py took 0.915 seconds
[2024-04-02T01:19:17.002+0000] {processor.py:161} INFO - Started process (PID=170) to work on /opt/airflow/dags/download_NASA_API_dags.py
[2024-04-02T01:19:17.003+0000] {processor.py:830} INFO - Processing file /opt/airflow/dags/download_NASA_API_dags.py for tasks to queue
[2024-04-02T01:19:17.005+0000] {logging_mixin.py:188} INFO - [2024-04-02T01:19:17.005+0000] {dagbag.py:540} INFO - Filling up the DagBag from /opt/airflow/dags/download_NASA_API_dags.py
[2024-04-02T01:19:17.721+0000] {logging_mixin.py:188} INFO - [2024-04-02T01:19:17.713+0000] {dagbag.py:350} ERROR - Failed to import: /opt/airflow/dags/download_NASA_API_dags.py
Traceback (most recent call last):
  File "/home/airflow/.local/lib/python3.8/site-packages/airflow/models/dagbag.py", line 346, in parse
    loader.exec_module(new_module)
  File "<frozen importlib._bootstrap_external>", line 843, in exec_module
  File "<frozen importlib._bootstrap>", line 219, in _call_with_frames_removed
  File "/opt/airflow/dags/download_NASA_API_dags.py", line 15, in <module>
    os.makedirs(output_estado_raw, exist_ok=True)
  File "/usr/local/lib/python3.8/os.py", line 213, in makedirs
    makedirs(head, exist_ok=exist_ok)
  File "/usr/local/lib/python3.8/os.py", line 213, in makedirs
    makedirs(head, exist_ok=exist_ok)
  File "/usr/local/lib/python3.8/os.py", line 223, in makedirs
    mkdir(name, mode)
PermissionError: [Errno 13] Permission denied: '/usr/local/airflow'
[2024-04-02T01:19:17.721+0000] {processor.py:842} WARNING - No viable dags retrieved from /opt/airflow/dags/download_NASA_API_dags.py
[2024-04-02T01:19:17.772+0000] {processor.py:183} INFO - Processing /opt/airflow/dags/download_NASA_API_dags.py took 0.773 seconds
[2024-04-02T01:19:48.120+0000] {processor.py:161} INFO - Started process (PID=173) to work on /opt/airflow/dags/download_NASA_API_dags.py
[2024-04-02T01:19:48.121+0000] {processor.py:830} INFO - Processing file /opt/airflow/dags/download_NASA_API_dags.py for tasks to queue
[2024-04-02T01:19:48.123+0000] {logging_mixin.py:188} INFO - [2024-04-02T01:19:48.122+0000] {dagbag.py:540} INFO - Filling up the DagBag from /opt/airflow/dags/download_NASA_API_dags.py
[2024-04-02T01:19:48.769+0000] {logging_mixin.py:188} INFO - [2024-04-02T01:19:48.762+0000] {dagbag.py:350} ERROR - Failed to import: /opt/airflow/dags/download_NASA_API_dags.py
Traceback (most recent call last):
  File "/home/airflow/.local/lib/python3.8/site-packages/airflow/models/dagbag.py", line 346, in parse
    loader.exec_module(new_module)
  File "<frozen importlib._bootstrap_external>", line 843, in exec_module
  File "<frozen importlib._bootstrap>", line 219, in _call_with_frames_removed
  File "/opt/airflow/dags/download_NASA_API_dags.py", line 15, in <module>
    os.makedirs(output_estado_raw, exist_ok=True)
  File "/usr/local/lib/python3.8/os.py", line 213, in makedirs
    makedirs(head, exist_ok=exist_ok)
  File "/usr/local/lib/python3.8/os.py", line 213, in makedirs
    makedirs(head, exist_ok=exist_ok)
  File "/usr/local/lib/python3.8/os.py", line 223, in makedirs
    mkdir(name, mode)
PermissionError: [Errno 13] Permission denied: '/usr/local/airflow'
[2024-04-02T01:19:48.770+0000] {processor.py:842} WARNING - No viable dags retrieved from /opt/airflow/dags/download_NASA_API_dags.py
[2024-04-02T01:19:48.833+0000] {processor.py:183} INFO - Processing /opt/airflow/dags/download_NASA_API_dags.py took 0.716 seconds
[2024-04-02T01:20:19.167+0000] {processor.py:161} INFO - Started process (PID=176) to work on /opt/airflow/dags/download_NASA_API_dags.py
[2024-04-02T01:20:19.169+0000] {processor.py:830} INFO - Processing file /opt/airflow/dags/download_NASA_API_dags.py for tasks to queue
[2024-04-02T01:20:19.170+0000] {logging_mixin.py:188} INFO - [2024-04-02T01:20:19.170+0000] {dagbag.py:540} INFO - Filling up the DagBag from /opt/airflow/dags/download_NASA_API_dags.py
[2024-04-02T01:20:19.864+0000] {logging_mixin.py:188} INFO - [2024-04-02T01:20:19.855+0000] {dagbag.py:350} ERROR - Failed to import: /opt/airflow/dags/download_NASA_API_dags.py
Traceback (most recent call last):
  File "/home/airflow/.local/lib/python3.8/site-packages/airflow/models/dagbag.py", line 346, in parse
    loader.exec_module(new_module)
  File "<frozen importlib._bootstrap_external>", line 843, in exec_module
  File "<frozen importlib._bootstrap>", line 219, in _call_with_frames_removed
  File "/opt/airflow/dags/download_NASA_API_dags.py", line 15, in <module>
    os.makedirs(output_estado_raw, exist_ok=True)
  File "/usr/local/lib/python3.8/os.py", line 213, in makedirs
    makedirs(head, exist_ok=exist_ok)
  File "/usr/local/lib/python3.8/os.py", line 213, in makedirs
    makedirs(head, exist_ok=exist_ok)
  File "/usr/local/lib/python3.8/os.py", line 223, in makedirs
    mkdir(name, mode)
PermissionError: [Errno 13] Permission denied: '/usr/local/airflow'
[2024-04-02T01:20:19.865+0000] {processor.py:842} WARNING - No viable dags retrieved from /opt/airflow/dags/download_NASA_API_dags.py
[2024-04-02T01:20:19.925+0000] {processor.py:183} INFO - Processing /opt/airflow/dags/download_NASA_API_dags.py took 0.761 seconds
[2024-04-02T01:20:50.332+0000] {processor.py:161} INFO - Started process (PID=179) to work on /opt/airflow/dags/download_NASA_API_dags.py
[2024-04-02T01:20:50.334+0000] {processor.py:830} INFO - Processing file /opt/airflow/dags/download_NASA_API_dags.py for tasks to queue
[2024-04-02T01:20:50.336+0000] {logging_mixin.py:188} INFO - [2024-04-02T01:20:50.336+0000] {dagbag.py:540} INFO - Filling up the DagBag from /opt/airflow/dags/download_NASA_API_dags.py
[2024-04-02T01:20:51.057+0000] {logging_mixin.py:188} INFO - [2024-04-02T01:20:51.049+0000] {dagbag.py:350} ERROR - Failed to import: /opt/airflow/dags/download_NASA_API_dags.py
Traceback (most recent call last):
  File "/home/airflow/.local/lib/python3.8/site-packages/airflow/models/dagbag.py", line 346, in parse
    loader.exec_module(new_module)
  File "<frozen importlib._bootstrap_external>", line 843, in exec_module
  File "<frozen importlib._bootstrap>", line 219, in _call_with_frames_removed
  File "/opt/airflow/dags/download_NASA_API_dags.py", line 15, in <module>
    os.makedirs(output_estado_raw, exist_ok=True)
  File "/usr/local/lib/python3.8/os.py", line 213, in makedirs
    makedirs(head, exist_ok=exist_ok)
  File "/usr/local/lib/python3.8/os.py", line 213, in makedirs
    makedirs(head, exist_ok=exist_ok)
  File "/usr/local/lib/python3.8/os.py", line 223, in makedirs
    mkdir(name, mode)
PermissionError: [Errno 13] Permission denied: '/usr/local/airflow'
[2024-04-02T01:20:51.058+0000] {processor.py:842} WARNING - No viable dags retrieved from /opt/airflow/dags/download_NASA_API_dags.py
[2024-04-02T01:20:51.118+0000] {processor.py:183} INFO - Processing /opt/airflow/dags/download_NASA_API_dags.py took 0.790 seconds
[2024-04-02T01:21:21.569+0000] {processor.py:161} INFO - Started process (PID=182) to work on /opt/airflow/dags/download_NASA_API_dags.py
[2024-04-02T01:21:21.571+0000] {processor.py:830} INFO - Processing file /opt/airflow/dags/download_NASA_API_dags.py for tasks to queue
[2024-04-02T01:21:21.573+0000] {logging_mixin.py:188} INFO - [2024-04-02T01:21:21.572+0000] {dagbag.py:540} INFO - Filling up the DagBag from /opt/airflow/dags/download_NASA_API_dags.py
[2024-04-02T01:21:22.253+0000] {logging_mixin.py:188} INFO - [2024-04-02T01:21:22.244+0000] {dagbag.py:350} ERROR - Failed to import: /opt/airflow/dags/download_NASA_API_dags.py
Traceback (most recent call last):
  File "/home/airflow/.local/lib/python3.8/site-packages/airflow/models/dagbag.py", line 346, in parse
    loader.exec_module(new_module)
  File "<frozen importlib._bootstrap_external>", line 843, in exec_module
  File "<frozen importlib._bootstrap>", line 219, in _call_with_frames_removed
  File "/opt/airflow/dags/download_NASA_API_dags.py", line 15, in <module>
    os.makedirs(output_estado_raw, exist_ok=True)
  File "/usr/local/lib/python3.8/os.py", line 213, in makedirs
    makedirs(head, exist_ok=exist_ok)
  File "/usr/local/lib/python3.8/os.py", line 213, in makedirs
    makedirs(head, exist_ok=exist_ok)
  File "/usr/local/lib/python3.8/os.py", line 223, in makedirs
    mkdir(name, mode)
PermissionError: [Errno 13] Permission denied: '/usr/local/airflow'
[2024-04-02T01:21:22.254+0000] {processor.py:842} WARNING - No viable dags retrieved from /opt/airflow/dags/download_NASA_API_dags.py
[2024-04-02T01:21:22.314+0000] {processor.py:183} INFO - Processing /opt/airflow/dags/download_NASA_API_dags.py took 0.749 seconds
[2024-04-02T01:21:52.423+0000] {processor.py:161} INFO - Started process (PID=185) to work on /opt/airflow/dags/download_NASA_API_dags.py
[2024-04-02T01:21:52.424+0000] {processor.py:830} INFO - Processing file /opt/airflow/dags/download_NASA_API_dags.py for tasks to queue
[2024-04-02T01:21:52.426+0000] {logging_mixin.py:188} INFO - [2024-04-02T01:21:52.425+0000] {dagbag.py:540} INFO - Filling up the DagBag from /opt/airflow/dags/download_NASA_API_dags.py
[2024-04-02T01:21:53.106+0000] {logging_mixin.py:188} INFO - [2024-04-02T01:21:53.098+0000] {dagbag.py:350} ERROR - Failed to import: /opt/airflow/dags/download_NASA_API_dags.py
Traceback (most recent call last):
  File "/home/airflow/.local/lib/python3.8/site-packages/airflow/models/dagbag.py", line 346, in parse
    loader.exec_module(new_module)
  File "<frozen importlib._bootstrap_external>", line 843, in exec_module
  File "<frozen importlib._bootstrap>", line 219, in _call_with_frames_removed
  File "/opt/airflow/dags/download_NASA_API_dags.py", line 15, in <module>
    os.makedirs(output_estado_raw, exist_ok=True)
  File "/usr/local/lib/python3.8/os.py", line 213, in makedirs
    makedirs(head, exist_ok=exist_ok)
  File "/usr/local/lib/python3.8/os.py", line 213, in makedirs
    makedirs(head, exist_ok=exist_ok)
  File "/usr/local/lib/python3.8/os.py", line 223, in makedirs
    mkdir(name, mode)
PermissionError: [Errno 13] Permission denied: '/usr/local/airflow'
[2024-04-02T01:21:53.107+0000] {processor.py:842} WARNING - No viable dags retrieved from /opt/airflow/dags/download_NASA_API_dags.py
[2024-04-02T01:21:53.159+0000] {processor.py:183} INFO - Processing /opt/airflow/dags/download_NASA_API_dags.py took 0.740 seconds
[2024-04-02T01:22:23.385+0000] {processor.py:161} INFO - Started process (PID=188) to work on /opt/airflow/dags/download_NASA_API_dags.py
[2024-04-02T01:22:23.386+0000] {processor.py:830} INFO - Processing file /opt/airflow/dags/download_NASA_API_dags.py for tasks to queue
[2024-04-02T01:22:23.388+0000] {logging_mixin.py:188} INFO - [2024-04-02T01:22:23.387+0000] {dagbag.py:540} INFO - Filling up the DagBag from /opt/airflow/dags/download_NASA_API_dags.py
[2024-04-02T01:22:24.037+0000] {logging_mixin.py:188} INFO - [2024-04-02T01:22:24.029+0000] {dagbag.py:350} ERROR - Failed to import: /opt/airflow/dags/download_NASA_API_dags.py
Traceback (most recent call last):
  File "/home/airflow/.local/lib/python3.8/site-packages/airflow/models/dagbag.py", line 346, in parse
    loader.exec_module(new_module)
  File "<frozen importlib._bootstrap_external>", line 843, in exec_module
  File "<frozen importlib._bootstrap>", line 219, in _call_with_frames_removed
  File "/opt/airflow/dags/download_NASA_API_dags.py", line 15, in <module>
    os.makedirs(output_estado_raw, exist_ok=True)
  File "/usr/local/lib/python3.8/os.py", line 213, in makedirs
    makedirs(head, exist_ok=exist_ok)
  File "/usr/local/lib/python3.8/os.py", line 213, in makedirs
    makedirs(head, exist_ok=exist_ok)
  File "/usr/local/lib/python3.8/os.py", line 223, in makedirs
    mkdir(name, mode)
PermissionError: [Errno 13] Permission denied: '/usr/local/airflow'
[2024-04-02T01:22:24.038+0000] {processor.py:842} WARNING - No viable dags retrieved from /opt/airflow/dags/download_NASA_API_dags.py
[2024-04-02T01:22:24.096+0000] {processor.py:183} INFO - Processing /opt/airflow/dags/download_NASA_API_dags.py took 0.715 seconds
[2024-04-02T01:22:54.503+0000] {processor.py:161} INFO - Started process (PID=191) to work on /opt/airflow/dags/download_NASA_API_dags.py
[2024-04-02T01:22:54.505+0000] {processor.py:830} INFO - Processing file /opt/airflow/dags/download_NASA_API_dags.py for tasks to queue
[2024-04-02T01:22:54.506+0000] {logging_mixin.py:188} INFO - [2024-04-02T01:22:54.506+0000] {dagbag.py:540} INFO - Filling up the DagBag from /opt/airflow/dags/download_NASA_API_dags.py
[2024-04-02T01:22:55.192+0000] {logging_mixin.py:188} INFO - [2024-04-02T01:22:55.183+0000] {dagbag.py:350} ERROR - Failed to import: /opt/airflow/dags/download_NASA_API_dags.py
Traceback (most recent call last):
  File "/home/airflow/.local/lib/python3.8/site-packages/airflow/models/dagbag.py", line 346, in parse
    loader.exec_module(new_module)
  File "<frozen importlib._bootstrap_external>", line 843, in exec_module
  File "<frozen importlib._bootstrap>", line 219, in _call_with_frames_removed
  File "/opt/airflow/dags/download_NASA_API_dags.py", line 15, in <module>
    os.makedirs(output_estado_raw, exist_ok=True)
  File "/usr/local/lib/python3.8/os.py", line 213, in makedirs
    makedirs(head, exist_ok=exist_ok)
  File "/usr/local/lib/python3.8/os.py", line 213, in makedirs
    makedirs(head, exist_ok=exist_ok)
  File "/usr/local/lib/python3.8/os.py", line 223, in makedirs
    mkdir(name, mode)
PermissionError: [Errno 13] Permission denied: '/usr/local/airflow'
[2024-04-02T01:22:55.193+0000] {processor.py:842} WARNING - No viable dags retrieved from /opt/airflow/dags/download_NASA_API_dags.py
[2024-04-02T01:22:55.254+0000] {processor.py:183} INFO - Processing /opt/airflow/dags/download_NASA_API_dags.py took 0.755 seconds
[2024-04-02T01:23:25.623+0000] {processor.py:161} INFO - Started process (PID=194) to work on /opt/airflow/dags/download_NASA_API_dags.py
[2024-04-02T01:23:25.624+0000] {processor.py:830} INFO - Processing file /opt/airflow/dags/download_NASA_API_dags.py for tasks to queue
[2024-04-02T01:23:25.626+0000] {logging_mixin.py:188} INFO - [2024-04-02T01:23:25.626+0000] {dagbag.py:540} INFO - Filling up the DagBag from /opt/airflow/dags/download_NASA_API_dags.py
[2024-04-02T01:23:26.307+0000] {logging_mixin.py:188} INFO - [2024-04-02T01:23:26.299+0000] {dagbag.py:350} ERROR - Failed to import: /opt/airflow/dags/download_NASA_API_dags.py
Traceback (most recent call last):
  File "/home/airflow/.local/lib/python3.8/site-packages/airflow/models/dagbag.py", line 346, in parse
    loader.exec_module(new_module)
  File "<frozen importlib._bootstrap_external>", line 843, in exec_module
  File "<frozen importlib._bootstrap>", line 219, in _call_with_frames_removed
  File "/opt/airflow/dags/download_NASA_API_dags.py", line 15, in <module>
    os.makedirs(output_estado_raw, exist_ok=True)
  File "/usr/local/lib/python3.8/os.py", line 213, in makedirs
    makedirs(head, exist_ok=exist_ok)
  File "/usr/local/lib/python3.8/os.py", line 213, in makedirs
    makedirs(head, exist_ok=exist_ok)
  File "/usr/local/lib/python3.8/os.py", line 223, in makedirs
    mkdir(name, mode)
PermissionError: [Errno 13] Permission denied: '/usr/local/airflow'
[2024-04-02T01:23:26.308+0000] {processor.py:842} WARNING - No viable dags retrieved from /opt/airflow/dags/download_NASA_API_dags.py
[2024-04-02T01:23:26.370+0000] {processor.py:183} INFO - Processing /opt/airflow/dags/download_NASA_API_dags.py took 0.750 seconds
[2024-04-02T01:23:56.754+0000] {processor.py:161} INFO - Started process (PID=197) to work on /opt/airflow/dags/download_NASA_API_dags.py
[2024-04-02T01:23:56.755+0000] {processor.py:830} INFO - Processing file /opt/airflow/dags/download_NASA_API_dags.py for tasks to queue
[2024-04-02T01:23:56.757+0000] {logging_mixin.py:188} INFO - [2024-04-02T01:23:56.756+0000] {dagbag.py:540} INFO - Filling up the DagBag from /opt/airflow/dags/download_NASA_API_dags.py
[2024-04-02T01:23:57.505+0000] {logging_mixin.py:188} INFO - [2024-04-02T01:23:57.498+0000] {dagbag.py:350} ERROR - Failed to import: /opt/airflow/dags/download_NASA_API_dags.py
Traceback (most recent call last):
  File "/home/airflow/.local/lib/python3.8/site-packages/airflow/models/dagbag.py", line 346, in parse
    loader.exec_module(new_module)
  File "<frozen importlib._bootstrap_external>", line 843, in exec_module
  File "<frozen importlib._bootstrap>", line 219, in _call_with_frames_removed
  File "/opt/airflow/dags/download_NASA_API_dags.py", line 15, in <module>
    os.makedirs(output_estado_raw, exist_ok=True)
  File "/usr/local/lib/python3.8/os.py", line 213, in makedirs
    makedirs(head, exist_ok=exist_ok)
  File "/usr/local/lib/python3.8/os.py", line 213, in makedirs
    makedirs(head, exist_ok=exist_ok)
  File "/usr/local/lib/python3.8/os.py", line 223, in makedirs
    mkdir(name, mode)
PermissionError: [Errno 13] Permission denied: '/usr/local/airflow'
[2024-04-02T01:23:57.506+0000] {processor.py:842} WARNING - No viable dags retrieved from /opt/airflow/dags/download_NASA_API_dags.py
[2024-04-02T01:23:57.565+0000] {processor.py:183} INFO - Processing /opt/airflow/dags/download_NASA_API_dags.py took 0.815 seconds
[2024-04-02T01:24:27.960+0000] {processor.py:161} INFO - Started process (PID=200) to work on /opt/airflow/dags/download_NASA_API_dags.py
[2024-04-02T01:24:27.961+0000] {processor.py:830} INFO - Processing file /opt/airflow/dags/download_NASA_API_dags.py for tasks to queue
[2024-04-02T01:24:27.964+0000] {logging_mixin.py:188} INFO - [2024-04-02T01:24:27.963+0000] {dagbag.py:540} INFO - Filling up the DagBag from /opt/airflow/dags/download_NASA_API_dags.py
[2024-04-02T01:24:28.721+0000] {logging_mixin.py:188} INFO - [2024-04-02T01:24:28.714+0000] {dagbag.py:350} ERROR - Failed to import: /opt/airflow/dags/download_NASA_API_dags.py
Traceback (most recent call last):
  File "/home/airflow/.local/lib/python3.8/site-packages/airflow/models/dagbag.py", line 346, in parse
    loader.exec_module(new_module)
  File "<frozen importlib._bootstrap_external>", line 843, in exec_module
  File "<frozen importlib._bootstrap>", line 219, in _call_with_frames_removed
  File "/opt/airflow/dags/download_NASA_API_dags.py", line 15, in <module>
    os.makedirs(output_estado_raw, exist_ok=True)
  File "/usr/local/lib/python3.8/os.py", line 213, in makedirs
    makedirs(head, exist_ok=exist_ok)
  File "/usr/local/lib/python3.8/os.py", line 213, in makedirs
    makedirs(head, exist_ok=exist_ok)
  File "/usr/local/lib/python3.8/os.py", line 223, in makedirs
    mkdir(name, mode)
PermissionError: [Errno 13] Permission denied: '/usr/local/airflow'
[2024-04-02T01:24:28.721+0000] {processor.py:842} WARNING - No viable dags retrieved from /opt/airflow/dags/download_NASA_API_dags.py
[2024-04-02T01:24:28.784+0000] {processor.py:183} INFO - Processing /opt/airflow/dags/download_NASA_API_dags.py took 0.827 seconds
[2024-04-02T01:24:58.963+0000] {processor.py:161} INFO - Started process (PID=203) to work on /opt/airflow/dags/download_NASA_API_dags.py
[2024-04-02T01:24:58.964+0000] {processor.py:830} INFO - Processing file /opt/airflow/dags/download_NASA_API_dags.py for tasks to queue
[2024-04-02T01:24:58.966+0000] {logging_mixin.py:188} INFO - [2024-04-02T01:24:58.965+0000] {dagbag.py:540} INFO - Filling up the DagBag from /opt/airflow/dags/download_NASA_API_dags.py
[2024-04-02T01:24:59.619+0000] {logging_mixin.py:188} INFO - [2024-04-02T01:24:59.609+0000] {dagbag.py:350} ERROR - Failed to import: /opt/airflow/dags/download_NASA_API_dags.py
Traceback (most recent call last):
  File "/home/airflow/.local/lib/python3.8/site-packages/airflow/models/dagbag.py", line 346, in parse
    loader.exec_module(new_module)
  File "<frozen importlib._bootstrap_external>", line 843, in exec_module
  File "<frozen importlib._bootstrap>", line 219, in _call_with_frames_removed
  File "/opt/airflow/dags/download_NASA_API_dags.py", line 15, in <module>
    os.makedirs(output_estado_raw, exist_ok=True)
  File "/usr/local/lib/python3.8/os.py", line 213, in makedirs
    makedirs(head, exist_ok=exist_ok)
  File "/usr/local/lib/python3.8/os.py", line 213, in makedirs
    makedirs(head, exist_ok=exist_ok)
  File "/usr/local/lib/python3.8/os.py", line 223, in makedirs
    mkdir(name, mode)
PermissionError: [Errno 13] Permission denied: '/usr/local/airflow'
[2024-04-02T01:24:59.620+0000] {processor.py:842} WARNING - No viable dags retrieved from /opt/airflow/dags/download_NASA_API_dags.py
[2024-04-02T01:24:59.685+0000] {processor.py:183} INFO - Processing /opt/airflow/dags/download_NASA_API_dags.py took 0.726 seconds
[2024-04-02T01:25:30.070+0000] {processor.py:161} INFO - Started process (PID=206) to work on /opt/airflow/dags/download_NASA_API_dags.py
[2024-04-02T01:25:30.071+0000] {processor.py:830} INFO - Processing file /opt/airflow/dags/download_NASA_API_dags.py for tasks to queue
[2024-04-02T01:25:30.073+0000] {logging_mixin.py:188} INFO - [2024-04-02T01:25:30.072+0000] {dagbag.py:540} INFO - Filling up the DagBag from /opt/airflow/dags/download_NASA_API_dags.py
[2024-04-02T01:25:30.731+0000] {logging_mixin.py:188} INFO - [2024-04-02T01:25:30.724+0000] {dagbag.py:350} ERROR - Failed to import: /opt/airflow/dags/download_NASA_API_dags.py
Traceback (most recent call last):
  File "/home/airflow/.local/lib/python3.8/site-packages/airflow/models/dagbag.py", line 346, in parse
    loader.exec_module(new_module)
  File "<frozen importlib._bootstrap_external>", line 843, in exec_module
  File "<frozen importlib._bootstrap>", line 219, in _call_with_frames_removed
  File "/opt/airflow/dags/download_NASA_API_dags.py", line 15, in <module>
    os.makedirs(output_estado_raw, exist_ok=True)
  File "/usr/local/lib/python3.8/os.py", line 213, in makedirs
    makedirs(head, exist_ok=exist_ok)
  File "/usr/local/lib/python3.8/os.py", line 213, in makedirs
    makedirs(head, exist_ok=exist_ok)
  File "/usr/local/lib/python3.8/os.py", line 223, in makedirs
    mkdir(name, mode)
PermissionError: [Errno 13] Permission denied: '/usr/local/airflow'
[2024-04-02T01:25:30.732+0000] {processor.py:842} WARNING - No viable dags retrieved from /opt/airflow/dags/download_NASA_API_dags.py
[2024-04-02T01:25:30.795+0000] {processor.py:183} INFO - Processing /opt/airflow/dags/download_NASA_API_dags.py took 0.729 seconds
[2024-04-02T01:26:01.001+0000] {processor.py:161} INFO - Started process (PID=209) to work on /opt/airflow/dags/download_NASA_API_dags.py
[2024-04-02T01:26:01.002+0000] {processor.py:830} INFO - Processing file /opt/airflow/dags/download_NASA_API_dags.py for tasks to queue
[2024-04-02T01:26:01.004+0000] {logging_mixin.py:188} INFO - [2024-04-02T01:26:01.003+0000] {dagbag.py:540} INFO - Filling up the DagBag from /opt/airflow/dags/download_NASA_API_dags.py
[2024-04-02T01:26:01.683+0000] {logging_mixin.py:188} INFO - [2024-04-02T01:26:01.675+0000] {dagbag.py:350} ERROR - Failed to import: /opt/airflow/dags/download_NASA_API_dags.py
Traceback (most recent call last):
  File "/home/airflow/.local/lib/python3.8/site-packages/airflow/models/dagbag.py", line 346, in parse
    loader.exec_module(new_module)
  File "<frozen importlib._bootstrap_external>", line 843, in exec_module
  File "<frozen importlib._bootstrap>", line 219, in _call_with_frames_removed
  File "/opt/airflow/dags/download_NASA_API_dags.py", line 15, in <module>
    os.makedirs(output_estado_raw, exist_ok=True)
  File "/usr/local/lib/python3.8/os.py", line 213, in makedirs
    makedirs(head, exist_ok=exist_ok)
  File "/usr/local/lib/python3.8/os.py", line 213, in makedirs
    makedirs(head, exist_ok=exist_ok)
  File "/usr/local/lib/python3.8/os.py", line 223, in makedirs
    mkdir(name, mode)
PermissionError: [Errno 13] Permission denied: '/usr/local/airflow'
[2024-04-02T01:26:01.684+0000] {processor.py:842} WARNING - No viable dags retrieved from /opt/airflow/dags/download_NASA_API_dags.py
[2024-04-02T01:26:01.745+0000] {processor.py:183} INFO - Processing /opt/airflow/dags/download_NASA_API_dags.py took 0.747 seconds
[2024-04-02T01:26:31.977+0000] {processor.py:161} INFO - Started process (PID=212) to work on /opt/airflow/dags/download_NASA_API_dags.py
[2024-04-02T01:26:31.980+0000] {processor.py:830} INFO - Processing file /opt/airflow/dags/download_NASA_API_dags.py for tasks to queue
[2024-04-02T01:26:31.981+0000] {logging_mixin.py:188} INFO - [2024-04-02T01:26:31.981+0000] {dagbag.py:540} INFO - Filling up the DagBag from /opt/airflow/dags/download_NASA_API_dags.py
[2024-04-02T01:26:32.745+0000] {logging_mixin.py:188} INFO - [2024-04-02T01:26:32.737+0000] {dagbag.py:350} ERROR - Failed to import: /opt/airflow/dags/download_NASA_API_dags.py
Traceback (most recent call last):
  File "/home/airflow/.local/lib/python3.8/site-packages/airflow/models/dagbag.py", line 346, in parse
    loader.exec_module(new_module)
  File "<frozen importlib._bootstrap_external>", line 843, in exec_module
  File "<frozen importlib._bootstrap>", line 219, in _call_with_frames_removed
  File "/opt/airflow/dags/download_NASA_API_dags.py", line 15, in <module>
    os.makedirs(output_estado_raw, exist_ok=True)
  File "/usr/local/lib/python3.8/os.py", line 213, in makedirs
    makedirs(head, exist_ok=exist_ok)
  File "/usr/local/lib/python3.8/os.py", line 213, in makedirs
    makedirs(head, exist_ok=exist_ok)
  File "/usr/local/lib/python3.8/os.py", line 223, in makedirs
    mkdir(name, mode)
PermissionError: [Errno 13] Permission denied: '/usr/local/airflow'
[2024-04-02T01:26:32.746+0000] {processor.py:842} WARNING - No viable dags retrieved from /opt/airflow/dags/download_NASA_API_dags.py
[2024-04-02T01:26:32.802+0000] {processor.py:183} INFO - Processing /opt/airflow/dags/download_NASA_API_dags.py took 0.830 seconds
[2024-04-02T01:27:02.979+0000] {processor.py:161} INFO - Started process (PID=215) to work on /opt/airflow/dags/download_NASA_API_dags.py
[2024-04-02T01:27:02.981+0000] {processor.py:830} INFO - Processing file /opt/airflow/dags/download_NASA_API_dags.py for tasks to queue
[2024-04-02T01:27:02.983+0000] {logging_mixin.py:188} INFO - [2024-04-02T01:27:02.982+0000] {dagbag.py:540} INFO - Filling up the DagBag from /opt/airflow/dags/download_NASA_API_dags.py
[2024-04-02T01:27:03.650+0000] {logging_mixin.py:188} INFO - [2024-04-02T01:27:03.641+0000] {dagbag.py:350} ERROR - Failed to import: /opt/airflow/dags/download_NASA_API_dags.py
Traceback (most recent call last):
  File "/home/airflow/.local/lib/python3.8/site-packages/airflow/models/dagbag.py", line 346, in parse
    loader.exec_module(new_module)
  File "<frozen importlib._bootstrap_external>", line 843, in exec_module
  File "<frozen importlib._bootstrap>", line 219, in _call_with_frames_removed
  File "/opt/airflow/dags/download_NASA_API_dags.py", line 15, in <module>
    os.makedirs(output_estado_raw, exist_ok=True)
  File "/usr/local/lib/python3.8/os.py", line 213, in makedirs
    makedirs(head, exist_ok=exist_ok)
  File "/usr/local/lib/python3.8/os.py", line 213, in makedirs
    makedirs(head, exist_ok=exist_ok)
  File "/usr/local/lib/python3.8/os.py", line 223, in makedirs
    mkdir(name, mode)
PermissionError: [Errno 13] Permission denied: '/usr/local/airflow'
[2024-04-02T01:27:03.651+0000] {processor.py:842} WARNING - No viable dags retrieved from /opt/airflow/dags/download_NASA_API_dags.py
[2024-04-02T01:27:03.718+0000] {processor.py:183} INFO - Processing /opt/airflow/dags/download_NASA_API_dags.py took 0.743 seconds
[2024-04-02T01:27:34.101+0000] {processor.py:161} INFO - Started process (PID=218) to work on /opt/airflow/dags/download_NASA_API_dags.py
[2024-04-02T01:27:34.103+0000] {processor.py:830} INFO - Processing file /opt/airflow/dags/download_NASA_API_dags.py for tasks to queue
[2024-04-02T01:27:34.105+0000] {logging_mixin.py:188} INFO - [2024-04-02T01:27:34.104+0000] {dagbag.py:540} INFO - Filling up the DagBag from /opt/airflow/dags/download_NASA_API_dags.py
[2024-04-02T01:27:34.787+0000] {logging_mixin.py:188} INFO - [2024-04-02T01:27:34.777+0000] {dagbag.py:350} ERROR - Failed to import: /opt/airflow/dags/download_NASA_API_dags.py
Traceback (most recent call last):
  File "/home/airflow/.local/lib/python3.8/site-packages/airflow/models/dagbag.py", line 346, in parse
    loader.exec_module(new_module)
  File "<frozen importlib._bootstrap_external>", line 843, in exec_module
  File "<frozen importlib._bootstrap>", line 219, in _call_with_frames_removed
  File "/opt/airflow/dags/download_NASA_API_dags.py", line 15, in <module>
    os.makedirs(output_estado_raw, exist_ok=True)
  File "/usr/local/lib/python3.8/os.py", line 213, in makedirs
    makedirs(head, exist_ok=exist_ok)
  File "/usr/local/lib/python3.8/os.py", line 213, in makedirs
    makedirs(head, exist_ok=exist_ok)
  File "/usr/local/lib/python3.8/os.py", line 223, in makedirs
    mkdir(name, mode)
PermissionError: [Errno 13] Permission denied: '/usr/local/airflow'
[2024-04-02T01:27:34.788+0000] {processor.py:842} WARNING - No viable dags retrieved from /opt/airflow/dags/download_NASA_API_dags.py
[2024-04-02T01:27:34.853+0000] {processor.py:183} INFO - Processing /opt/airflow/dags/download_NASA_API_dags.py took 0.755 seconds
[2024-04-02T01:28:05.222+0000] {processor.py:161} INFO - Started process (PID=221) to work on /opt/airflow/dags/download_NASA_API_dags.py
[2024-04-02T01:28:05.224+0000] {processor.py:830} INFO - Processing file /opt/airflow/dags/download_NASA_API_dags.py for tasks to queue
[2024-04-02T01:28:05.226+0000] {logging_mixin.py:188} INFO - [2024-04-02T01:28:05.226+0000] {dagbag.py:540} INFO - Filling up the DagBag from /opt/airflow/dags/download_NASA_API_dags.py
[2024-04-02T01:28:05.866+0000] {logging_mixin.py:188} INFO - [2024-04-02T01:28:05.858+0000] {dagbag.py:350} ERROR - Failed to import: /opt/airflow/dags/download_NASA_API_dags.py
Traceback (most recent call last):
  File "/home/airflow/.local/lib/python3.8/site-packages/airflow/models/dagbag.py", line 346, in parse
    loader.exec_module(new_module)
  File "<frozen importlib._bootstrap_external>", line 843, in exec_module
  File "<frozen importlib._bootstrap>", line 219, in _call_with_frames_removed
  File "/opt/airflow/dags/download_NASA_API_dags.py", line 15, in <module>
    os.makedirs(output_estado_raw, exist_ok=True)
  File "/usr/local/lib/python3.8/os.py", line 213, in makedirs
    makedirs(head, exist_ok=exist_ok)
  File "/usr/local/lib/python3.8/os.py", line 213, in makedirs
    makedirs(head, exist_ok=exist_ok)
  File "/usr/local/lib/python3.8/os.py", line 223, in makedirs
    mkdir(name, mode)
PermissionError: [Errno 13] Permission denied: '/usr/local/airflow'
[2024-04-02T01:28:05.867+0000] {processor.py:842} WARNING - No viable dags retrieved from /opt/airflow/dags/download_NASA_API_dags.py
[2024-04-02T01:28:05.927+0000] {processor.py:183} INFO - Processing /opt/airflow/dags/download_NASA_API_dags.py took 0.708 seconds
[2024-04-02T01:28:36.346+0000] {processor.py:161} INFO - Started process (PID=224) to work on /opt/airflow/dags/download_NASA_API_dags.py
[2024-04-02T01:28:36.348+0000] {processor.py:830} INFO - Processing file /opt/airflow/dags/download_NASA_API_dags.py for tasks to queue
[2024-04-02T01:28:36.350+0000] {logging_mixin.py:188} INFO - [2024-04-02T01:28:36.349+0000] {dagbag.py:540} INFO - Filling up the DagBag from /opt/airflow/dags/download_NASA_API_dags.py
[2024-04-02T01:28:37.037+0000] {logging_mixin.py:188} INFO - [2024-04-02T01:28:37.028+0000] {dagbag.py:350} ERROR - Failed to import: /opt/airflow/dags/download_NASA_API_dags.py
Traceback (most recent call last):
  File "/home/airflow/.local/lib/python3.8/site-packages/airflow/models/dagbag.py", line 346, in parse
    loader.exec_module(new_module)
  File "<frozen importlib._bootstrap_external>", line 843, in exec_module
  File "<frozen importlib._bootstrap>", line 219, in _call_with_frames_removed
  File "/opt/airflow/dags/download_NASA_API_dags.py", line 15, in <module>
    os.makedirs(output_estado_raw, exist_ok=True)
  File "/usr/local/lib/python3.8/os.py", line 213, in makedirs
    makedirs(head, exist_ok=exist_ok)
  File "/usr/local/lib/python3.8/os.py", line 213, in makedirs
    makedirs(head, exist_ok=exist_ok)
  File "/usr/local/lib/python3.8/os.py", line 223, in makedirs
    mkdir(name, mode)
PermissionError: [Errno 13] Permission denied: '/usr/local/airflow'
[2024-04-02T01:28:37.038+0000] {processor.py:842} WARNING - No viable dags retrieved from /opt/airflow/dags/download_NASA_API_dags.py
[2024-04-02T01:28:37.096+0000] {processor.py:183} INFO - Processing /opt/airflow/dags/download_NASA_API_dags.py took 0.754 seconds
[2024-04-02T01:29:07.361+0000] {processor.py:161} INFO - Started process (PID=227) to work on /opt/airflow/dags/download_NASA_API_dags.py
[2024-04-02T01:29:07.363+0000] {processor.py:830} INFO - Processing file /opt/airflow/dags/download_NASA_API_dags.py for tasks to queue
[2024-04-02T01:29:07.365+0000] {logging_mixin.py:188} INFO - [2024-04-02T01:29:07.364+0000] {dagbag.py:540} INFO - Filling up the DagBag from /opt/airflow/dags/download_NASA_API_dags.py
[2024-04-02T01:29:08.052+0000] {logging_mixin.py:188} INFO - [2024-04-02T01:29:08.043+0000] {dagbag.py:350} ERROR - Failed to import: /opt/airflow/dags/download_NASA_API_dags.py
Traceback (most recent call last):
  File "/home/airflow/.local/lib/python3.8/site-packages/airflow/models/dagbag.py", line 346, in parse
    loader.exec_module(new_module)
  File "<frozen importlib._bootstrap_external>", line 843, in exec_module
  File "<frozen importlib._bootstrap>", line 219, in _call_with_frames_removed
  File "/opt/airflow/dags/download_NASA_API_dags.py", line 15, in <module>
    os.makedirs(output_estado_raw, exist_ok=True)
  File "/usr/local/lib/python3.8/os.py", line 213, in makedirs
    makedirs(head, exist_ok=exist_ok)
  File "/usr/local/lib/python3.8/os.py", line 213, in makedirs
    makedirs(head, exist_ok=exist_ok)
  File "/usr/local/lib/python3.8/os.py", line 223, in makedirs
    mkdir(name, mode)
PermissionError: [Errno 13] Permission denied: '/usr/local/airflow'
[2024-04-02T01:29:08.053+0000] {processor.py:842} WARNING - No viable dags retrieved from /opt/airflow/dags/download_NASA_API_dags.py
[2024-04-02T01:29:08.115+0000] {processor.py:183} INFO - Processing /opt/airflow/dags/download_NASA_API_dags.py took 0.759 seconds
[2024-04-02T01:29:38.501+0000] {processor.py:161} INFO - Started process (PID=230) to work on /opt/airflow/dags/download_NASA_API_dags.py
[2024-04-02T01:29:38.502+0000] {processor.py:830} INFO - Processing file /opt/airflow/dags/download_NASA_API_dags.py for tasks to queue
[2024-04-02T01:29:38.504+0000] {logging_mixin.py:188} INFO - [2024-04-02T01:29:38.503+0000] {dagbag.py:540} INFO - Filling up the DagBag from /opt/airflow/dags/download_NASA_API_dags.py
[2024-04-02T01:29:39.095+0000] {logging_mixin.py:188} INFO - [2024-04-02T01:29:39.088+0000] {dagbag.py:350} ERROR - Failed to import: /opt/airflow/dags/download_NASA_API_dags.py
Traceback (most recent call last):
  File "/home/airflow/.local/lib/python3.8/site-packages/airflow/models/dagbag.py", line 346, in parse
    loader.exec_module(new_module)
  File "<frozen importlib._bootstrap_external>", line 843, in exec_module
  File "<frozen importlib._bootstrap>", line 219, in _call_with_frames_removed
  File "/opt/airflow/dags/download_NASA_API_dags.py", line 15, in <module>
    os.makedirs(output_estado_raw, exist_ok=True)
  File "/usr/local/lib/python3.8/os.py", line 213, in makedirs
    makedirs(head, exist_ok=exist_ok)
  File "/usr/local/lib/python3.8/os.py", line 213, in makedirs
    makedirs(head, exist_ok=exist_ok)
  File "/usr/local/lib/python3.8/os.py", line 223, in makedirs
    mkdir(name, mode)
PermissionError: [Errno 13] Permission denied: '/usr/local/airflow'
[2024-04-02T01:29:39.096+0000] {processor.py:842} WARNING - No viable dags retrieved from /opt/airflow/dags/download_NASA_API_dags.py
[2024-04-02T01:29:39.159+0000] {processor.py:183} INFO - Processing /opt/airflow/dags/download_NASA_API_dags.py took 0.661 seconds
[2024-04-02T01:30:09.493+0000] {processor.py:161} INFO - Started process (PID=233) to work on /opt/airflow/dags/download_NASA_API_dags.py
[2024-04-02T01:30:09.495+0000] {processor.py:830} INFO - Processing file /opt/airflow/dags/download_NASA_API_dags.py for tasks to queue
[2024-04-02T01:30:09.496+0000] {logging_mixin.py:188} INFO - [2024-04-02T01:30:09.496+0000] {dagbag.py:540} INFO - Filling up the DagBag from /opt/airflow/dags/download_NASA_API_dags.py
[2024-04-02T01:30:10.116+0000] {logging_mixin.py:188} INFO - [2024-04-02T01:30:10.108+0000] {dagbag.py:350} ERROR - Failed to import: /opt/airflow/dags/download_NASA_API_dags.py
Traceback (most recent call last):
  File "/home/airflow/.local/lib/python3.8/site-packages/airflow/models/dagbag.py", line 346, in parse
    loader.exec_module(new_module)
  File "<frozen importlib._bootstrap_external>", line 843, in exec_module
  File "<frozen importlib._bootstrap>", line 219, in _call_with_frames_removed
  File "/opt/airflow/dags/download_NASA_API_dags.py", line 15, in <module>
    os.makedirs(output_estado_raw, exist_ok=True)
  File "/usr/local/lib/python3.8/os.py", line 213, in makedirs
    makedirs(head, exist_ok=exist_ok)
  File "/usr/local/lib/python3.8/os.py", line 213, in makedirs
    makedirs(head, exist_ok=exist_ok)
  File "/usr/local/lib/python3.8/os.py", line 223, in makedirs
    mkdir(name, mode)
PermissionError: [Errno 13] Permission denied: '/usr/local/airflow'
[2024-04-02T01:30:10.117+0000] {processor.py:842} WARNING - No viable dags retrieved from /opt/airflow/dags/download_NASA_API_dags.py
[2024-04-02T01:30:10.169+0000] {processor.py:183} INFO - Processing /opt/airflow/dags/download_NASA_API_dags.py took 0.679 seconds
[2024-04-02T01:30:40.521+0000] {processor.py:161} INFO - Started process (PID=236) to work on /opt/airflow/dags/download_NASA_API_dags.py
[2024-04-02T01:30:40.522+0000] {processor.py:830} INFO - Processing file /opt/airflow/dags/download_NASA_API_dags.py for tasks to queue
[2024-04-02T01:30:40.524+0000] {logging_mixin.py:188} INFO - [2024-04-02T01:30:40.523+0000] {dagbag.py:540} INFO - Filling up the DagBag from /opt/airflow/dags/download_NASA_API_dags.py
[2024-04-02T01:30:41.196+0000] {logging_mixin.py:188} INFO - [2024-04-02T01:30:41.188+0000] {dagbag.py:350} ERROR - Failed to import: /opt/airflow/dags/download_NASA_API_dags.py
Traceback (most recent call last):
  File "/home/airflow/.local/lib/python3.8/site-packages/airflow/models/dagbag.py", line 346, in parse
    loader.exec_module(new_module)
  File "<frozen importlib._bootstrap_external>", line 843, in exec_module
  File "<frozen importlib._bootstrap>", line 219, in _call_with_frames_removed
  File "/opt/airflow/dags/download_NASA_API_dags.py", line 15, in <module>
    os.makedirs(output_estado_raw, exist_ok=True)
  File "/usr/local/lib/python3.8/os.py", line 213, in makedirs
    makedirs(head, exist_ok=exist_ok)
  File "/usr/local/lib/python3.8/os.py", line 213, in makedirs
    makedirs(head, exist_ok=exist_ok)
  File "/usr/local/lib/python3.8/os.py", line 223, in makedirs
    mkdir(name, mode)
PermissionError: [Errno 13] Permission denied: '/usr/local/airflow'
[2024-04-02T01:30:41.197+0000] {processor.py:842} WARNING - No viable dags retrieved from /opt/airflow/dags/download_NASA_API_dags.py
[2024-04-02T01:30:41.272+0000] {processor.py:183} INFO - Processing /opt/airflow/dags/download_NASA_API_dags.py took 0.755 seconds
[2024-04-02T01:31:11.658+0000] {processor.py:161} INFO - Started process (PID=239) to work on /opt/airflow/dags/download_NASA_API_dags.py
[2024-04-02T01:31:11.659+0000] {processor.py:830} INFO - Processing file /opt/airflow/dags/download_NASA_API_dags.py for tasks to queue
[2024-04-02T01:31:11.661+0000] {logging_mixin.py:188} INFO - [2024-04-02T01:31:11.661+0000] {dagbag.py:540} INFO - Filling up the DagBag from /opt/airflow/dags/download_NASA_API_dags.py
[2024-04-02T01:31:12.707+0000] {logging_mixin.py:188} INFO - [2024-04-02T01:31:12.699+0000] {dagbag.py:350} ERROR - Failed to import: /opt/airflow/dags/download_NASA_API_dags.py
Traceback (most recent call last):
  File "/home/airflow/.local/lib/python3.8/site-packages/airflow/models/dagbag.py", line 346, in parse
    loader.exec_module(new_module)
  File "<frozen importlib._bootstrap_external>", line 843, in exec_module
  File "<frozen importlib._bootstrap>", line 219, in _call_with_frames_removed
  File "/opt/airflow/dags/download_NASA_API_dags.py", line 15, in <module>
    os.makedirs(output_estado_raw, exist_ok=True)
  File "/usr/local/lib/python3.8/os.py", line 213, in makedirs
    makedirs(head, exist_ok=exist_ok)
  File "/usr/local/lib/python3.8/os.py", line 213, in makedirs
    makedirs(head, exist_ok=exist_ok)
  File "/usr/local/lib/python3.8/os.py", line 223, in makedirs
    mkdir(name, mode)
PermissionError: [Errno 13] Permission denied: '/usr/local/airflow'
[2024-04-02T01:31:12.709+0000] {processor.py:842} WARNING - No viable dags retrieved from /opt/airflow/dags/download_NASA_API_dags.py
[2024-04-02T01:31:12.768+0000] {processor.py:183} INFO - Processing /opt/airflow/dags/download_NASA_API_dags.py took 1.115 seconds
[2024-04-02T01:31:43.172+0000] {processor.py:161} INFO - Started process (PID=242) to work on /opt/airflow/dags/download_NASA_API_dags.py
[2024-04-02T01:31:43.173+0000] {processor.py:830} INFO - Processing file /opt/airflow/dags/download_NASA_API_dags.py for tasks to queue
[2024-04-02T01:31:43.175+0000] {logging_mixin.py:188} INFO - [2024-04-02T01:31:43.175+0000] {dagbag.py:540} INFO - Filling up the DagBag from /opt/airflow/dags/download_NASA_API_dags.py
[2024-04-02T01:31:43.820+0000] {logging_mixin.py:188} INFO - [2024-04-02T01:31:43.812+0000] {dagbag.py:350} ERROR - Failed to import: /opt/airflow/dags/download_NASA_API_dags.py
Traceback (most recent call last):
  File "/home/airflow/.local/lib/python3.8/site-packages/airflow/models/dagbag.py", line 346, in parse
    loader.exec_module(new_module)
  File "<frozen importlib._bootstrap_external>", line 843, in exec_module
  File "<frozen importlib._bootstrap>", line 219, in _call_with_frames_removed
  File "/opt/airflow/dags/download_NASA_API_dags.py", line 15, in <module>
    os.makedirs(output_estado_raw, exist_ok=True)
  File "/usr/local/lib/python3.8/os.py", line 213, in makedirs
    makedirs(head, exist_ok=exist_ok)
  File "/usr/local/lib/python3.8/os.py", line 213, in makedirs
    makedirs(head, exist_ok=exist_ok)
  File "/usr/local/lib/python3.8/os.py", line 223, in makedirs
    mkdir(name, mode)
PermissionError: [Errno 13] Permission denied: '/usr/local/airflow'
[2024-04-02T01:31:43.821+0000] {processor.py:842} WARNING - No viable dags retrieved from /opt/airflow/dags/download_NASA_API_dags.py
[2024-04-02T01:31:43.881+0000] {processor.py:183} INFO - Processing /opt/airflow/dags/download_NASA_API_dags.py took 0.713 seconds
