[2024-04-06T16:55:12.897+0000] {taskinstance.py:1979} INFO - Dependencies all met for dep_context=non-requeueable deps ti=<TaskInstance: data_processing_dag.standardize_data scheduled__2024-04-05T00:00:00+00:00 [queued]>
[2024-04-06T16:55:12.919+0000] {taskinstance.py:1979} INFO - Dependencies all met for dep_context=requeueable deps ti=<TaskInstance: data_processing_dag.standardize_data scheduled__2024-04-05T00:00:00+00:00 [queued]>
[2024-04-06T16:55:12.919+0000] {taskinstance.py:2193} INFO - Starting attempt 2 of 2
[2024-04-06T16:55:12.976+0000] {taskinstance.py:2217} INFO - Executing <Task(PythonOperator): standardize_data> on 2024-04-05 00:00:00+00:00
[2024-04-06T16:55:12.982+0000] {standard_task_runner.py:60} INFO - Started process 427 to run task
[2024-04-06T16:55:12.986+0000] {standard_task_runner.py:87} INFO - Running: ['airflow', 'tasks', 'run', 'data_processing_dag', 'standardize_data', 'scheduled__2024-04-05T00:00:00+00:00', '--job-id', '33', '--raw', '--subdir', 'DAGS_FOLDER/download_NASA_API_dags.py', '--cfg-path', '/tmp/tmp5r15g6rw']
[2024-04-06T16:55:12.988+0000] {standard_task_runner.py:88} INFO - Job 33: Subtask standardize_data
[2024-04-06T16:55:13.092+0000] {task_command.py:423} INFO - Running <TaskInstance: data_processing_dag.standardize_data scheduled__2024-04-05T00:00:00+00:00 [running]> on host 29c65f98c54a
[2024-04-06T16:55:13.248+0000] {taskinstance.py:2513} INFO - Exporting env vars: AIRFLOW_CTX_DAG_OWNER='airflow' AIRFLOW_CTX_DAG_ID='data_processing_dag' AIRFLOW_CTX_TASK_ID='standardize_data' AIRFLOW_CTX_EXECUTION_DATE='2024-04-05T00:00:00+00:00' AIRFLOW_CTX_TRY_NUMBER='2' AIRFLOW_CTX_DAG_RUN_ID='scheduled__2024-04-05T00:00:00+00:00'
[2024-04-06T16:55:13.250+0000] {taskinstance.py:2731} ERROR - Task failed with exception
Traceback (most recent call last):
  File "/home/airflow/.local/lib/python3.8/site-packages/airflow/models/taskinstance.py", line 444, in _execute_task
    result = _execute_callable(context=context, **execute_callable_kwargs)
  File "/home/airflow/.local/lib/python3.8/site-packages/airflow/models/taskinstance.py", line 414, in _execute_callable
    return execute_callable(context=context, **execute_callable_kwargs)
  File "/home/airflow/.local/lib/python3.8/site-packages/airflow/operators/python.py", line 200, in execute
    return_value = self.execute_callable()
  File "/home/airflow/.local/lib/python3.8/site-packages/airflow/operators/python.py", line 217, in execute_callable
    return self.python_callable(*self.op_args, **self.op_kwargs)
  File "/opt/airflow/dags/download_NASA_API_dags.py", line 94, in standardize_data
    df_combinado.columns = new_columns
NameError: name 'df_combinado' is not defined
[2024-04-06T16:55:13.273+0000] {taskinstance.py:1149} INFO - Marking task as FAILED. dag_id=data_processing_dag, task_id=standardize_data, execution_date=20240405T000000, start_date=20240406T165512, end_date=20240406T165513
[2024-04-06T16:55:13.329+0000] {standard_task_runner.py:107} ERROR - Failed to execute job 33 for task standardize_data (name 'df_combinado' is not defined; 427)
[2024-04-06T16:55:13.361+0000] {local_task_job_runner.py:234} INFO - Task exited with return code 1
[2024-04-06T16:55:13.402+0000] {taskinstance.py:3312} INFO - 0 downstream tasks scheduled from follow-on schedule check
